Workbook
Name lst_AbsenceReason: #REF!
Name lst_AttendanceType: #REF!
Name lst_BeneficiaryStatus: #REF!
Name lst_Centers: #REF!
Name lst_Companion: #REF!
Name lst_Diagnosis: tbl_Lists_1[التشخيص]
Name lst_EmployeeStatus: #REF!
Name lst_FeeType: tbl_Lists #REF!
Name lst_Gender: #REF!
Name lst_JobTitles: #REF!
Name lst_Levels: #REF!
Name lst_LocationSpecialty: #REF!
Name lst_LocationType: #REF!
Name lst_Period: #REF!
Name lst_ProgramMode: #REF!
Name lst_ServiceCategory: #REF!
Name lst_Services: #REF!
Name lst_SessionStatus: #REF!
Name lst_SessionType: #REF!
Name lst_Severity: #REF!
Name lst_Specializations: #REF!
Name lst_StatusType: #REF!
Name lst_Tracks: #REF!
Name قائمة_جلسة: 'القوائم المرجعية'!$L$5:$L$10
Name قائمة_خدمة: 'القوائم المرجعية'!$U$5:$U$8

Sheet الموظفين
A1: م | B1: الرقم الوظيفي | C1: الاسم | D1: الوظيفة | E1: التخصص | F1: فني / إداري | G1: الخدمة_الأساسية | H1: المركز | I1: الفترة | J1: ملاحظات
A2: 1 | B2: E001 | C2: موظف1 | D2: أخصائي اجتماعي | E2: اجتماعي | F2: فني | G2: الخدمة الاجتماعية | H2: مدرسة إرادة للتعليم (مكة) | I2: صباحي
A3: 2 | B3: E002 | C3: موظف2 | D3: أخصائي علاج وظيفي | E3: علاج وظيفي | F3: فني | G3: العلاج الوظيفي | H3: مدرسة إرادة للتعليم (مكة) | I3: مسائي
A4: 3 | B4: E003 | C4: موظف3 | D4: أخصائي نطق | E4: نطق وتواصل | F4: فني | G4: النطق والتواصل | H4: مدرسة إرادة وتمكين لمتلازمة داون (نجد) | I4: مسائي
A5: 4 | B5: E004 | C5: موظف4 | D5: أخصائي نفسي | E5: نفسي | F5: فني | G5: التأهيل النفسي | H5: مركز إرادة وتمكين لرعاية ذوي الاحتياجات الخاصة (جلمودة) | I5: كلاهما
A6: 5 | B6: E005 | C6: موظف5 | D6: أخصائي تربية خاصة | E6: تربية خاصة | F6: فني | G6: التربية الخاصة | H6: مركز إرادة وتمكين للرعاية النهارية (القدس) | I6: مسائي
A7: 6 | B7: E006 | C7: موظف6 | D7: أخصائي علاج وظيفي | E7: علاج وظيفي | F7: فني | G7: العلاج الوظيفي | H7: مركز إرادة وتمكين لمتلازمة داون (نجد) | I7: صباحي
A8: 7 | B8: E007 | C8: موظف7 | D8: أخصائي تربية خاصة | E8: تربية خاصة | F8: فني | G8: التربية الخاصة | H8: مدرسة إرادة للتعليم (مكة) | I8: صباحي
A9: 8 | B9: E008 | C9: موظف8 | D9: أخصائي نطق | E9: نطق وتواصل | F9: فني | G9: النطق والتواصل | H9: مدرسة إرادة وتمكين لمتلازمة داون (نجد) | I9: كلاهما
A10: 9 | B10: E009 | C10: موظف9 | D10: أخصائي علاج طبيعي | E10: علاج طبيعي | F10: فني | G10: العلاج الطبيعي | H10: مدرسة إرادة للتعليم (مكة) | I10: كلاهما
A11: 10 | B11: E010 | C11: موظف10 | D11: أخصائي علاج طبيعي | E11: علاج طبيعي | F11: فني | G11: العلاج الطبيعي | H11: مدرسة إرادة للتعليم (مكة) | I11: مسائي
A12: 11 | B12: E011 | C12: موظف11 | D12: مساعدة معلمة | E12: تربية خاصة | F12: إداري | G12: التربية الخاصة | H12: مركز إرادة وتمكين لرعاية ذوي الاحتياجات الخاصة (جلمودة) | I12: صباحي
A13: 12 | B13: E012 | C13: موظف12 | D13: إدارية | E13: اجتماعي | F13: إداري | G13: الخدمة الاجتماعية | H13: مدرسة إرادة للتعليم (مكة) | I13: صباحي
... A106: 105 | B106: E105 | C106: موظف105 | D106: أخصائي اجتماعي | E106: اجتماعي | F106: فني | G106: الخدمة الاجتماعية | H106: مركز إرادة وتمكين للرعاية النهارية (القدس) | I106: مسائي

Sheet المستفيدين
A1: م | B1: هوية المستفيد | C1: الاسم | D1: الجنس | E1: تاريخ_الميلاد | F1: المركز | G1: الفترة | H1: تاريخ_الالتحاق | I1: التشخيص | J1: IQ | K1: نوع البرنامج الأساسي | L1: مبلغ_الرسوم | M1: مصادر الرسوم | N1: التربية الخاصة | O1: النطق والتواصل | P1: العلاج الطبيعي | Q1: العلاج الوظيفي | R1: التأهيل النفسي | S1: التأهيل النفسي الحركي | T1: اجمالي الجلسات
A2: 1 | B2: 1025469854 | C2: مستفيد1 | D2: أنثى | E2: 42882 | F2: مركز إرادة وتمكين للرعاية النهارية (القدس) | G2: مسائي | H2: 45106 | I2: =IFERROR(INDEX('تشخيص الحالات'!$D$2:$D$1001,SUMPRODUCT(('تشخيص الحالات'!$B$2:$B$1001=B2)*('تشخيص الحالات'!$G$2:$G$1001=1)*ROW('تشخيص الحالات'!$B$2:$B$1001))-1),"")&IF(SUMPRODUCT(('تشخيص الحالات'!$B$2:$B$1001=B2)*('تشخيص الحالات'!$G$2:$G$1001=2))>0,"، "&IFERROR(INDEX('تشخيص الحالات'!$D$2:$D$1001,SUMPRODUCT(('تشخيص الحالات'!$B$2:$B$1001=B2)*('تشخيص الحالات'!$G$2:$G$1001=2)*ROW('تشخيص الحالات'!$B$2:$B$1001))-1),""),"")&IF(SUMPRODUCT(('تشخيص الحالات'!$B$2:$B$1001=B2)*('تشخيص الحالات'!$G$2:$G$1001=3))>0,"، "&IFERROR(INDEX('تشخيص الحالات'!$D$2:$D$1001,SUMPRODUCT(('تشخيص الحالات'!$B$2:$B$1001=B2)*('تشخيص الحالات'!$G$2:$G$1001=3)*ROW('تشخيص الحالات'!$B$2:$B$1001))-1),""),"")&IF(SUMPRODUCT(('تشخيص الحالات'!$B$2:$B$1001=B2)*('تشخيص الحالات'!$G$2:$G$1001=4))>0,"، "&IFERROR(INDEX('تشخيص الحالات'!$D$2:$D$1001,SUMPRODUCT(('تشخيص الحالات'!$B$2:$B$1001=B2)*('تشخيص الحالات'!$G$2:$G$1001=4)*ROW('تشخيص الحالات'!$B$2:$B$1001))-1),""),"")&IF(SUMPRODUCT(('تشخيص الحالات'!$B$2:$B$1001=B2)*('تشخيص الحالات'!$G$2:$G$1001=5))>0,"، "&IFERROR(INDEX('تشخيص الحالات'!$D$2:$D$1001,SUMPRODUCT(('تشخيص الحالات'!$B$2:$B$1001=B2)*('تشخيص الحالات'!$G$2:$G$1001=5)*ROW('تشخيص الحالات'!$B$2:$B$1001))-1),""),"")&IF(SUMPRODUCT(('تشخيص الحالات'!$B$2:$B$1001=B2)*('تشخيص الحالات'!$G$2:$G$1001=6))>0,"، "&IFERROR(INDEX('تشخيص الحالات'!$D$2:$D$1001,SUMPRODUCT(('تشخيص الحالات'!$B$2:$B$1001=B2)*('تشخيص الحالات'!$G$2:$G$1001=6)*ROW('تشخيص الحالات'!$B$2:$B$1001))-1),""),"")&IF(SUMPRODUCT(('تشخيص الحالات'!$B$2:$B$1001=B2)*('تشخيص الحالات'!$G$2:$G$1001=7))>0,"، "&IFERROR(INDEX('تشخيص الحالات'!$D$2:$D$1001,SUMPRODUCT(('تشخيص الحالات'!$B$2:$B$1001=B2)*('تشخيص الحالات'!$G$2:$G$1001=7)*ROW('تشخيص الحالات'!$B$2:$B$1001))-1),""),"")&IF(SUMPRODUCT(('تشخيص الحالات'!$B$2:$B$1001=B2)*('تشخيص الحالات'!$G$2:$G$1001=8))>0,"، "&IFERROR(INDEX('تشخيص الحالات'!$D$2:$D$1001,SUMPRODUCT(('تشخيص الحالات'!$B$2:$B$1001=B2)*('تشخيص الحالات'!$G$2:$G$1001=8)*ROW('تشخيص الحالات'!$B$2:$B$1001))-1),""),"") -> اضطراب تواصل اجتماعي، شلل دماغي | J2: =LEN(I2) -> 31 | K2: فصول | L2: 2000 | M2: شركة سابك | N2: 1 | O2: 0 | P2: 0 | Q2: 1 | R2: 0 | S2: 5 | T2: =SUM(tbl_Beneficiaries[[#This Row],[ التربية الخاصة ]:[ التأهيل النفسي الحركي ]]) -> 7 | V2: =_xlfn.TEXTJOIN("، ",TRUE,"a","b") -> a، b | W2: =_xlfn.CONCAT("a","b","c") -> abc | X2: =_xlfn.AGGREGATE(15,6,1/('تشخيص الحالات'!$B$2:$B$493=B2)*ROW('تشخيص الحالات'!$B$2:$B$493),1) -> 2
A3: 2 | B3: 1065397512 | C3: مستفيد2 | D3: أنثى | E3: 42398 | F3: مدرسة إرادة وتمكين لمتلازمة داون (نجد) | G3: مسائي | H3: 45068 | I3: =IFERROR(INDEX('تشخيص الحالات'!$D$2:$D$1001,SUMPRODUCT(('تشخيص الحالات'!$B$2:$B$1001=B3)*('تشخيص الحالات'!$G$2:$G$1001=1)*ROW('تشخيص الحالات'!$B$2:$B$1001))-1),"")&IF(SUMPRODUCT(('تشخيص الحالات'!$B$2:$B$1001=B3)*('تشخيص الحالات'!$G$2:$G$1001=2))>0,"، "&IFERROR(INDEX('تشخيص الحالات'!$D$2:$D$1001,SUMPRODUCT(('تشخيص الحالات'!$B$2:$B$1001=B3)*('تشخيص الحالات'!$G$2:$G$1001=2)*ROW('تشخيص الحالات'!$B$2:$B$1001))-1),""),"")&IF(SUMPRODUCT(('تشخيص الحالات'!$B$2:$B$1001=B3)*('تشخيص الحالات'!$G$2:$G$1001=3))>0,"، "&IFERROR(INDEX('تشخيص الحالات'!$D$2:$D$1001,SUMPRODUCT(('تشخيص الحالات'!$B$2:$B$1001=B3)*('تشخيص الحالات'!$G$2:$G$1001=3)*ROW('تشخيص الحالات'!$B$2:$B$1001))-1),""),"")&IF(SUMPRODUCT(('تشخيص الحالات'!$B$2:$B$1001=B3)*('تشخيص الحالات'!$G$2:$G$1001=4))>0,"، "&IFERROR(INDEX('تشخيص الحالات'!$D$2:$D$1001,SUMPRODUCT(('تشخيص الحالات'!$B$2:$B$1001=B3)*('تشخيص الحالات'!$G$2:$G$1001=4)*ROW('تشخيص الحالات'!$B$2:$B$1001))-1),""),"")&IF(SUMPRODUCT(('تشخيص الحالات'!$B$2:$B$1001=B3)*('تشخيص الحالات'!$G$2:$G$1001=5))>0,"، "&IFERROR(INDEX('تشخيص الحالات'!$D$2:$D$1001,SUMPRODUCT(('تشخيص الحالات'!$B$2:$B$1001=B3)*('تشخيص الحالات'!$G$2:$G$1001=5)*ROW('تشخيص الحالات'!$B$2:$B$1001))-1),""),"")&IF(SUMPRODUCT(('تشخيص الحالات'!$B$2:$B$1001=B3)*('تشخيص الحالات'!$G$2:$G$1001=6))>0,"، "&IFERROR(INDEX('تشخيص الحالات'!$D$2:$D$1001,SUMPRODUCT(('تشخيص الحالات'!$B$2:$B$1001=B3)*('تشخيص الحالات'!$G$2:$G$1001=6)*ROW('تشخيص الحالات'!$B$2:$B$1001))-1),""),"")&IF(SUMPRODUCT(('تشخيص الحالات'!$B$2:$B$1001=B3)*('تشخيص الحالات'!$G$2:$G$1001=7))>0,"، "&IFERROR(INDEX('تشخيص الحالات'!$D$2:$D$1001,SUMPRODUCT(('تشخيص الحالات'!$B$2:$B$1001=B3)*('تشخيص الحالات'!$G$2:$G$1001=7)*ROW('تشخيص الحالات'!$B$2:$B$1001))-1),""),"")&IF(SUMPRODUCT(('تشخيص الحالات'!$B$2:$B$1001=B3)*('تشخيص الحالات'!$G$2:$G$1001=8))>0,"، "&IFERROR(INDEX('تشخيص الحالات'!$D$2:$D$1001,SUMPRODUCT(('تشخيص الحالات'!$B$2:$B$1001=B3)*('تشخيص الحالات'!$G$2:$G$1001=8)*ROW('تشخيص الحالات'!$B$2:$B$1001))-1),""),"") -> اضطراب نفسي، إعاقة ذهنية | J3: 85 | K3: جلسات فردية | L3: 2500 | M3: أفراد | N3: 1 | O3: 1 | P3: 5 | Q3: 2 | R3: 0 | S3: 0 | T3: =SUM(tbl_Beneficiaries[[#This Row],[ التربية الخاصة ]:[ التأهيل النفسي الحركي ]]) -> 9
A4: 3 | B4: 1069735216 | C4: مستفيد3 | D4: أنثى | E4: 41766 | F4: مركز إرادة وتمكين للرعاية النهارية (القدس) | G4: مسائي | H4: 44032 | I4: =IFERROR(INDEX('تشخيص الحالات'!$D$2:$D$1001,SUMPRODUCT(('تشخيص الحالات'!$B$2:$B$1001=B4)*('تشخيص الحالات'!$G$2:$G$1001=1)*ROW('تشخيص الحالات'!$B$2:$B$1001))-1),"")&IF(SUMPRODUCT(('تشخيص الحالات'!$B$2:$B$1001=B4)*('تشخيص الحالات'!$G$2:$G$1001=2))>0,"، "&IFERROR(INDEX('تشخيص الحالات'!$D$2:$D$1001,SUMPRODUCT(('تشخيص الحالات'!$B$2:$B$1001=B4)*('تشخيص الحالات'!$G$2:$G$1001=2)*ROW('تشخيص الحالات'!$B$2:$B$1001))-1),""),"")&IF(SUMPRODUCT(('تشخيص الحالات'!$B$2:$B$1001=B4)*('تشخيص الحالات'!$G$2:$G$1001=3))>0,"، "&IFERROR(INDEX('تشخيص الحالات'!$D$2:$D$1001,SUMPRODUCT(('تشخيص الحالات'!$B$2:$B$1001=B4)*('تشخيص الحالات'!$G$2:$G$1001=3)*ROW('تشخيص الحالات'!$B$2:$B$1001))-1),""),"")&IF(SUMPRODUCT(('تشخيص الحالات'!$B$2:$B$1001=B4)*('تشخيص الحالات'!$G$2:$G$1001=4))>0,"، "&IFERROR(INDEX('تشخيص الحالات'!$D$2:$D$1001,SUMPRODUCT(('تشخيص الحالات'!$B$2:$B$1001=B4)*('تشخيص الحالات'!$G$2:$G$1001=4)*ROW('تشخيص الحالات'!$B$2:$B$1001))-1),""),"")&IF(SUMPRODUCT(('تشخيص الحالات'!$B$2:$B$1001=B4)*('تشخيص الحالات'!$G$2:$G$1001=5))>0,"، "&IFERROR(INDEX('تشخيص الحالات'!$D$2:$D$1001,SUMPRODUCT(('تشخيص الحالات'!$B$2:$B$1001=B4)*('تشخيص الحالات'!$G$2:$G$1001=5)*ROW('تشخيص الحالات'!$B$2:$B$1001))-1),""),"")&IF(SUMPRODUCT(('تشخيص الحالات'!$B$2:$B$1001=B4)*('تشخيص الحالات'!$G$2:$G$1001=6))>0,"، "&IFERROR(INDEX('تشخيص الحالات'!$D$2:$D$1001,SUMPRODUCT(('تشخيص الحالات'!$B$2:$B$1001=B4)*('تشخيص الحالات'!$G$2:$G$1001=6)*ROW('تشخيص الحالات'!$B$2:$B$1001))-1),""),"")&IF(SUMPRODUCT(('تشخيص الحالات'!$B$2:$B$1001=B4)*('تشخيص الحالات'!$G$2:$G$1001=7))>0,"، "&IFERROR(INDEX('تشخيص الحالات'!$D$2:$D$1001,SUMPRODUCT(('تشخيص الحالات'!$B$2:$B$1001=B4)*('تشخيص الحالات'!$G$2:$G$1001=7)*ROW('تشخيص الحالات'!$B$2:$B$1001))-1),""),"")&IF(SUMPRODUCT(('تشخيص الحالات'!$B$2:$B$1001=B4)*('تشخيص الحالات'!$G$2:$G$1001=8))>0,"، "&IFERROR(INDEX('تشخيص الحالات'!$D$2:$D$1001,SUMPRODUCT(('تشخيص الحالات'!$B$2:$B$1001=B4)*('تشخيص الحالات'!$G$2:$G$1001=8)*ROW('تشخيص الحالات'!$B$2:$B$1001))-1),""),"") -> متلازمة داون، فرط الحركة وتشتت الانتباه | J4: 60 | K4: فصول | L4: 3000 | M4: شركة حديد | N4: 5 | O4: 5 | P4: 0 | Q4: 0 | R4: 0 | S4: 1 | T4: =SUM(tbl_Beneficiaries[[#This Row],[ التربية الخاصة ]:[ التأهيل النفسي الحركي ]]) -> 11
A5: 4 | B5: 1096348523 | C5: مستفيد4 | D5: ذكر | E5: 43463 | F5: مدرسة إرادة للتعليم (مكة) | G5: مسائي | H5: 45091 | I5: =IFERROR(INDEX('تشخيص الحالات'!$D$2:$D$1001,SUMPRODUCT(('تشخيص الحالات'!$B$2:$B$1001=B5)*('تشخيص الحالات'!$G$2:$G$1001=1)*ROW('تشخيص الحالات'!$B$2:$B$1001))-1),"")&IF(SUMPRODUCT(('تشخيص الحالات'!$B$2:$B$1001=B5)*('تشخيص الحالات'!$G$2:$G$1001=2))>0,"، "&IFERROR(INDEX('تشخيص الحالات'!$D$2:$D$1001,SUMPRODUCT(('تشخيص الحالات'!$B$2:$B$1001=B5)*('تشخيص الحالات'!$G$2:$G$1001=2)*ROW('تشخيص الحالات'!$B$2:$B$1001))-1),""),"")&IF(SUMPRODUCT(('تشخيص الحالات'!$B$2:$B$1001=B5)*('تشخيص الحالات'!$G$2:$G$1001=3))>0,"، "&IFERROR(INDEX('تشخيص الحالات'!$D$2:$D$1001,SUMPRODUCT(('تشخيص الحالات'!$B$2:$B$1001=B5)*('تشخيص الحالات'!$G$2:$G$1001=3)*ROW('تشخيص الحالات'!$B$2:$B$1001))-1),""),"")&IF(SUMPRODUCT(('تشخيص الحالات'!$B$2:$B$1001=B5)*('تشخيص الحالات'!$G$2:$G$1001=4))>0,"، "&IFERROR(INDEX('تشخيص الحالات'!$D$2:$D$1001,SUMPRODUCT(('تشخيص الحالات'!$B$2:$B$1001=B5)*('تشخيص الحالات'!$G$2:$G$1001=4)*ROW('تشخيص الحالات'!$B$2:$B$1001))-1),""),"")&IF(SUMPRODUCT(('تشخيص الحالات'!$B$2:$B$1001=B5)*('تشخيص الحالات'!$G$2:$G$1001=5))>0,"، "&IFERROR(INDEX('تشخيص الحالات'!$D$2:$D$1001,SUMPRODUCT(('تشخيص الحالات'!$B$2:$B$1001=B5)*('تشخيص الحالات'!$G$2:$G$1001=5)*ROW('تشخيص الحالات'!$B$2:$B$1001))-1),""),"")&IF(SUMPRODUCT(('تشخيص الحالات'!$B$2:$B$1001=B5)*('تشخيص الحالات'!$G$2:$G$1001=6))>0,"، "&IFERROR(INDEX('تشخيص الحالات'!$D$2:$D$1001,SUMPRODUCT(('تشخيص الحالات'!$B$2:$B$1001=B5)*('تشخيص الحالات'!$G$2:$G$1001=6)*ROW('تشخيص الحالات'!$B$2:$B$1001))-1),""),"")&IF(SUMPRODUCT(('تشخيص الحالات'!$B$2:$B$1001=B5)*('تشخيص الحالات'!$G$2:$G$1001=7))>0,"، "&IFERROR(INDEX('تشخيص الحالات'!$D$2:$D$1001,SUMPRODUCT(('تشخيص الحالات'!$B$2:$B$1001=B5)*('تشخيص الحالات'!$G$2:$G$1001=7)*ROW('تشخيص الحالات'!$B$2:$B$1001))-1),""),"")&IF(SUMPRODUCT(('تشخيص الحالات'!$B$2:$B$1001=B5)*('تشخيص الحالات'!$G$2:$G$1001=8))>0,"، "&IFERROR(INDEX('تشخيص الحالات'!$D$2:$D$1001,SUMPRODUCT(('تشخيص الحالات'!$B$2:$B$1001=B5)*('تشخيص الحالات'!$G$2:$G$1001=8)*ROW('تشخيص الحالات'!$B$2:$B$1001))-1),""),"") -> متلازمة داون، اضطرابات سلوكية، إعاقة ذهنية | J5: 70 | K5: جلسات فردية | L5: 2000 | M5: شركة حديد | N5: 0 | O5: 0 | P5: 0 | Q5: 2 | R5: 3 | S5: 0 | T5: =SUM(tbl_Beneficiaries[[#This Row],[ التربية الخاصة ]:[ التأهيل النفسي الحركي ]]) -> 5
A6: 5 | B6: 1124422216 | C6: مستفيد5 | D6: أنثى | E6: 43191 | F6: مركز إرادة وتمكين لمتلازمة داون (نجد) | G6: صباحي | H6: 45376 | I6: =IFERROR(INDEX('تشخيص الحالات'!$D$2:$D$1001,SUMPRODUCT(('تشخيص الحالات'!$B$2:$B$1001=B6)*('تشخيص الحالات'!$G$2:$G$1001=1)*ROW('تشخيص الحالات'!$B$2:$B$1001))-1),"")&IF(SUMPRODUCT(('تشخيص الحالات'!$B$2:$B$1001=B6)*('تشخيص الحالات'!$G$2:$G$1001=2))>0,"، "&IFERROR(INDEX('تشخيص الحالات'!$D$2:$D$1001,SUMPRODUCT(('تشخيص الحالات'!$B$2:$B$1001=B6)*('تشخيص الحالات'!$G$2:$G$1001=2)*ROW('تشخيص الحالات'!$B$2:$B$1001))-1),""),"")&IF(SUMPRODUCT(('تشخيص الحالات'!$B$2:$B$1001=B6)*('تشخيص الحالات'!$G$2:$G$1001=3))>0,"، "&IFERROR(INDEX('تشخيص الحالات'!$D$2:$D$1001,SUMPRODUCT(('تشخيص الحالات'!$B$2:$B$1001=B6)*('تشخيص الحالات'!$G$2:$G$1001=3)*ROW('تشخيص الحالات'!$B$2:$B$1001))-1),""),"")&IF(SUMPRODUCT(('تشخيص الحالات'!$B$2:$B$1001=B6)*('تشخيص الحالات'!$G$2:$G$1001=4))>0,"، "&IFERROR(INDEX('تشخيص الحالات'!$D$2:$D$1001,SUMPRODUCT(('تشخيص الحالات'!$B$2:$B$1001=B6)*('تشخيص الحالات'!$G$2:$G$1001=4)*ROW('تشخيص الحالات'!$B$2:$B$1001))-1),""),"")&IF(SUMPRODUCT(('تشخيص الحالات'!$B$2:$B$1001=B6)*('تشخيص الحالات'!$G$2:$G$1001=5))>0,"، "&IFERROR(INDEX('تشخيص الحالات'!$D$2:$D$1001,SUMPRODUCT(('تشخيص الحالات'!$B$2:$B$1001=B6)*('تشخيص الحالات'!$G$2:$G$1001=5)*ROW('تشخيص الحالات'!$B$2:$B$1001))-1),""),"")&IF(SUMPRODUCT(('تشخيص الحالات'!$B$2:$B$1001=B6)*('تشخيص الحالات'!$G$2:$G$1001=6))>0,"، "&IFERROR(INDEX('تشخيص الحالات'!$D$2:$D$1001,SUMPRODUCT(('تشخيص الحالات'!$B$2:$B$1001=B6)*('تشخيص الحالات'!$G$2:$G$1001=6)*ROW('تشخيص الحالات'!$B$2:$B$1001))-1),""),"")&IF(SUMPRODUCT(('تشخيص الحالات'!$B$2:$B$1001=B6)*('تشخيص الحالات'!$G$2:$G$1001=7))>0,"، "&IFERROR(INDEX('تشخيص الحالات'!$D$2:$D$1001,SUMPRODUCT(('تشخيص الحالات'!$B$2:$B$1001=B6)*('تشخيص الحالات'!$G$2:$G$1001=7)*ROW('تشخيص الحالات'!$B$2:$B$1001))-1),""),"")&IF(SUMPRODUCT(('تشخيص الحالات'!$B$2:$B$1001=B6)*('تشخيص الحالات'!$G$2:$G$1001=8))>0,"، "&IFERROR(INDEX('تشخيص الحالات'!$D$2:$D$1001,SUMPRODUCT(('تشخيص الحالات'!$B$2:$B$1001=B6)*('تشخيص الحالات'!$G$2:$G$1001=8)*ROW('تشخيص الحالات'!$B$2:$B$1001))-1),""),"") -> مشكلات أسرية / اجتماعية، صعوبات تعلم، إعاقة بصرية، اضطراب تكامل حسي | J6: 100 | K6: كلاهما | L6: 1500 | M6: تأمين / شركات | N6: 0 | O6: 2 | P6: 0 | Q6: 0 | R6: 0 | S6: 0 | T6: =SUM(tbl_Beneficiaries[[#This Row],[ التربية الخاصة ]:[ التأهيل النفسي الحركي ]]) -> 2
A7: 6 | B7: 1889143921 | C7: مستفيد6 | D7: أنثى | E7: 41369 | F7: مركز إرادة وتمكين لرعاية ذوي الاحتياجات الخاصة (جلمودة) | G7: صباحي | H7: 45377 | I7: =IFERROR(INDEX('تشخيص الحالات'!$D$2:$D$1001,SUMPRODUCT(('تشخيص الحالات'!$B$2:$B$1001=B7)*('تشخيص الحالات'!$G$2:$G$1001=1)*ROW('تشخيص الحالات'!$B$2:$B$1001))-1),"")&IF(SUMPRODUCT(('تشخيص الحالات'!$B$2:$B$1001=B7)*('تشخيص الحالات'!$G$2:$G$1001=2))>0,"، "&IFERROR(INDEX('تشخيص الحالات'!$D$2:$D$1001,SUMPRODUCT(('تشخيص الحالات'!$B$2:$B$1001=B7)*('تشخيص الحالات'!$G$2:$G$1001=2)*ROW('تشخيص الحالات'!$B$2:$B$1001))-1),""),"")&IF(SUMPRODUCT(('تشخيص الحالات'!$B$2:$B$1001=B7)*('تشخيص الحالات'!$G$2:$G$1001=3))>0,"، "&IFERROR(INDEX('تشخيص الحالات'!$D$2:$D$1001,SUMPRODUCT(('تشخيص الحالات'!$B$2:$B$1001=B7)*('تشخيص الحالات'!$G$2:$G$1001=3)*ROW('تشخيص الحالات'!$B$2:$B$1001))-1),""),"")&IF(SUMPRODUCT(('تشخيص الحالات'!$B$2:$B$1001=B7)*('تشخيص الحالات'!$G$2:$G$1001=4))>0,"، "&IFERROR(INDEX('تشخيص الحالات'!$D$2:$D$1001,SUMPRODUCT(('تشخيص الحالات'!$B$2:$B$1001=B7)*('تشخيص الحالات'!$G$2:$G$1001=4)*ROW('تشخيص الحالات'!$B$2:$B$1001))-1),""),"")&IF(SUMPRODUCT(('تشخيص الحالات'!$B$2:$B$1001=B7)*('تشخيص الحالات'!$G$2:$G$1001=5))>0,"، "&IFERROR(INDEX('تشخيص الحالات'!$D$2:$D$1001,SUMPRODUCT(('تشخيص الحالات'!$B$2:$B$1001=B7)*('تشخيص الحالات'!$G$2:$G$1001=5)*ROW('تشخيص الحالات'!$B$2:$B$1001))-1),""),"")&IF(SUMPRODUCT(('تشخيص الحالات'!$B$2:$B$1001=B7)*('تشخيص الحالات'!$G$2:$G$1001=6))>0,"، "&IFERROR(INDEX('تشخيص الحالات'!$D$2:$D$1001,SUMPRODUCT(('تشخيص الحالات'!$B$2:$B$1001=B7)*('تشخيص الحالات'!$G$2:$G$1001=6)*ROW('تشخيص الحالات'!$B$2:$B$1001))-1),""),"")&IF(SUMPRODUCT(('تشخيص الحالات'!$B$2:$B$1001=B7)*('تشخيص الحالات'!$G$2:$G$1001=7))>0,"، "&IFERROR(INDEX('تشخيص الحالات'!$D$2:$D$1001,SUMPRODUCT(('تشخيص الحالات'!$B$2:$B$1001=B7)*('تشخيص الحالات'!$G$2:$G$1001=7)*ROW('تشخيص الحالات'!$B$2:$B$1001))-1),""),"")&IF(SUMPRODUCT(('تشخيص الحالات'!$B$2:$B$1001=B7)*('تشخيص الحالات'!$G$2:$G$1001=8))>0,"، "&IFERROR(INDEX('تشخيص الحالات'!$D$2:$D$1001,SUMPRODUCT(('تشخيص الحالات'!$B$2:$B$1001=B7)*('تشخيص الحالات'!$G$2:$G$1001=8)*ROW('تشخيص الحالات'!$B$2:$B$1001))-1),""),"") -> شلل دماغي، اضطراب تواصل اجتماعي، اضطرابات سلوكية، فرط الحركة وتشتت الانتباه | J7: 96 | K7: جلسات فردية | L7: 2500 | M7: شركة سابك | N7: 0 | O7: 0 | P7: 2 | Q7: 8 | R7: 3 | S7: 1 | T7: =SUM(tbl_Beneficiaries[[#This Row],[ التربية الخاصة ]:[ التأهيل النفسي الحركي ]]) -> 14
A8: 7 | B8: 1854312995 | C8: مستفيد7 | D8: ذكر | E8: 41308 | F8: مدرسة إرادة وتمكين لمتلازمة داون (نجد) | G8: مسائي | H8: 45298 | I8: =IFERROR(INDEX('تشخيص الحالات'!$D$2:$D$1001,SUMPRODUCT(('تشخيص الحالات'!$B$2:$B$1001=B8)*('تشخيص الحالات'!$G$2:$G$1001=1)*ROW('تشخيص الحالات'!$B$2:$B$1001))-1),"")&IF(SUMPRODUCT(('تشخيص الحالات'!$B$2:$B$1001=B8)*('تشخيص الحالات'!$G$2:$G$1001=2))>0,"، "&IFERROR(INDEX('تشخيص الحالات'!$D$2:$D$1001,SUMPRODUCT(('تشخيص الحالات'!$B$2:$B$1001=B8)*('تشخيص الحالات'!$G$2:$G$1001=2)*ROW('تشخيص الحالات'!$B$2:$B$1001))-1),""),"")&IF(SUMPRODUCT(('تشخيص الحالات'!$B$2:$B$1001=B8)*('تشخيص الحالات'!$G$2:$G$1001=3))>0,"، "&IFERROR(INDEX('تشخيص الحالات'!$D$2:$D$1001,SUMPRODUCT(('تشخيص الحالات'!$B$2:$B$1001=B8)*('تشخيص الحالات'!$G$2:$G$1001=3)*ROW('تشخيص الحالات'!$B$2:$B$1001))-1),""),"")&IF(SUMPRODUCT(('تشخيص الحالات'!$B$2:$B$1001=B8)*('تشخيص الحالات'!$G$2:$G$1001=4))>0,"، "&IFERROR(INDEX('تشخيص الحالات'!$D$2:$D$1001,SUMPRODUCT(('تشخيص الحالات'!$B$2:$B$1001=B8)*('تشخيص الحالات'!$G$2:$G$1001=4)*ROW('تشخيص الحالات'!$B$2:$B$1001))-1),""),"")&IF(SUMPRODUCT(('تشخيص الحالات'!$B$2:$B$1001=B8)*('تشخيص الحالات'!$G$2:$G$1001=5))>0,"، "&IFERROR(INDEX('تشخيص الحالات'!$D$2:$D$1001,SUMPRODUCT(('تشخيص الحالات'!$B$2:$B$1001=B8)*('تشخيص الحالات'!$G$2:$G$1001=5)*ROW('تشخيص الحالات'!$B$2:$B$1001))-1),""),"")&IF(SUMPRODUCT(('تشخيص الحالات'!$B$2:$B$1001=B8)*('تشخيص الحالات'!$G$2:$G$1001=6))>0,"، "&IFERROR(INDEX('تشخيص الحالات'!$D$2:$D$1001,SUMPRODUCT(('تشخيص الحالات'!$B$2:$B$1001=B8)*('تشخيص الحالات'!$G$2:$G$1001=6)*ROW('تشخيص الحالات'!$B$2:$B$1001))-1),""),"")&IF(SUMPRODUCT(('تشخيص الحالات'!$B$2:$B$1001=B8)*('تشخيص الحالات'!$G$2:$G$1001=7))>0,"، "&IFERROR(INDEX('تشخيص الحالات'!$D$2:$D$1001,SUMPRODUCT(('تشخيص الحالات'!$B$2:$B$1001=B8)*('تشخيص الحالات'!$G$2:$G$1001=7)*ROW('تشخيص الحالات'!$B$2:$B$1001))-1),""),"")&IF(SUMPRODUCT(('تشخيص الحالات'!$B$2:$B$1001=B8)*('تشخيص الحالات'!$G$2:$G$1001=8))>0,"، "&IFERROR(INDEX('تشخيص الحالات'!$D$2:$D$1001,SUMPRODUCT(('تشخيص الحالات'!$B$2:$B$1001=B8)*('تشخيص الحالات'!$G$2:$G$1001=8)*ROW('تشخيص الحالات'!$B$2:$B$1001))-1),""),"") -> تأخر حركي | J8: 50 | K8: كلاهما | L8: 4000 | M8: الشؤون الاجتماعية | N8: 0 | O8: 0 | P8: 0 | Q8: 7 | R8: 0 | S8: 0 | T8: =SUM(tbl_Beneficiaries[[#This Row],[ التربية الخاصة ]:[ التأهيل النفسي الحركي ]]) -> 7
A9: 8 | B9: 1911743491 | C9: مستفيد8 | D9: أنثى | E9: 43747 | F9: مركز إرادة وتمكين لمتلازمة داون (نجد) | G9: كلاهما | H9: 45368 | I9: =IFERROR(INDEX('تشخيص الحالات'!$D$2:$D$1001,SUMPRODUCT(('تشخيص الحالات'!$B$2:$B$1001=B9)*('تشخيص الحالات'!$G$2:$G$1001=1)*ROW('تشخيص الحالات'!$B$2:$B$1001))-1),"")&IF(SUMPRODUCT(('تشخيص الحالات'!$B$2:$B$1001=B9)*('تشخيص الحالات'!$G$2:$G$1001=2))>0,"، "&IFERROR(INDEX('تشخيص الحالات'!$D$2:$D$1001,SUMPRODUCT(('تشخيص الحالات'!$B$2:$B$1001=B9)*('تشخيص الحالات'!$G$2:$G$1001=2)*ROW('تشخيص الحالات'!$B$2:$B$1001))-1),""),"")&IF(SUMPRODUCT(('تشخيص الحالات'!$B$2:$B$1001=B9)*('تشخيص الحالات'!$G$2:$G$1001=3))>0,"، "&IFERROR(INDEX('تشخيص الحالات'!$D$2:$D$1001,SUMPRODUCT(('تشخيص الحالات'!$B$2:$B$1001=B9)*('تشخيص الحالات'!$G$2:$G$1001=3)*ROW('تشخيص الحالات'!$B$2:$B$1001))-1),""),"")&IF(SUMPRODUCT(('تشخيص الحالات'!$B$2:$B$1001=B9)*('تشخيص الحالات'!$G$2:$G$1001=4))>0,"، "&IFERROR(INDEX('تشخيص الحالات'!$D$2:$D$1001,SUMPRODUCT(('تشخيص الحالات'!$B$2:$B$1001=B9)*('تشخيص الحالات'!$G$2:$G$1001=4)*ROW('تشخيص الحالات'!$B$2:$B$1001))-1),""),"")&IF(SUMPRODUCT(('تشخيص الحالات'!$B$2:$B$1001=B9)*('تشخيص الحالات'!$G$2:$G$1001=5))>0,"، "&IFERROR(INDEX('تشخيص الحالات'!$D$2:$D$1001,SUMPRODUCT(('تشخيص الحالات'!$B$2:$B$1001=B9)*('تشخيص الحالات'!$G$2:$G$1001=5)*ROW('تشخيص الحالات'!$B$2:$B$1001))-1),""),"")&IF(SUMPRODUCT(('تشخيص الحالات'!$B$2:$B$1001=B9)*('تشخيص الحالات'!$G$2:$G$1001=6))>0,"، "&IFERROR(INDEX('تشخيص الحالات'!$D$2:$D$1001,SUMPRODUCT(('تشخيص الحالات'!$B$2:$B$1001=B9)*('تشخيص الحالات'!$G$2:$G$1001=6)*ROW('تشخيص الحالات'!$B$2:$B$1001))-1),""),"")&IF(SUMPRODUCT(('تشخيص الحالات'!$B$2:$B$1001=B9)*('تشخيص الحالات'!$G$2:$G$1001=7))>0,"، "&IFERROR(INDEX('تشخيص الحالات'!$D$2:$D$1001,SUMPRODUCT(('تشخيص الحالات'!$B$2:$B$1001=B9)*('تشخيص الحالات'!$G$2:$G$1001=7)*ROW('تشخيص الحالات'!$B$2:$B$1001))-1),""),"")&IF(SUMPRODUCT(('تشخيص الحالات'!$B$2:$B$1001=B9)*('تشخيص الحالات'!$G$2:$G$1001=8))>0,"، "&IFERROR(INDEX('تشخيص الحالات'!$D$2:$D$1001,SUMPRODUCT(('تشخيص الحالات'!$B$2:$B$1001=B9)*('تشخيص الحالات'!$G$2:$G$1001=8)*ROW('تشخيص الحالات'!$B$2:$B$1001))-1),""),"") -> فرط الحركة وتشتت الانتباه | J9: 69 | K9: جلسات فردية | L9: 2500 | M9: شركة سابك | N9: 0 | O9: 8 | P9: 0 | Q9: 8 | R9: 7 | S9: 0 | T9: =SUM(tbl_Beneficiaries[[#This Row],[ التربية الخاصة ]:[ التأهيل النفسي الحركي ]]) -> 23
A10: 9 | B10: 1347584820 | C10: مستفيد9 | D10: ذكر | E10: 40730 | F10: مركز إرادة وتمكين للرعاية النهارية (القدس) | G10: مسائي | H10: 44924 | I10: =IFERROR(INDEX('تشخيص الحالات'!$D$2:$D$1001,SUMPRODUCT(('تشخيص الحالات'!$B$2:$B$1001=B10)*('تشخيص الحالات'!$G$2:$G$1001=1)*ROW('تشخيص الحالات'!$B$2:$B$1001))-1),"")&IF(SUMPRODUCT(('تشخيص الحالات'!$B$2:$B$1001=B10)*('تشخيص الحالات'!$G$2:$G$1001=2))>0,"، "&IFERROR(INDEX('تشخيص الحالات'!$D$2:$D$1001,SUMPRODUCT(('تشخيص الحالات'!$B$2:$B$1001=B10)*('تشخيص الحالات'!$G$2:$G$1001=2)*ROW('تشخيص الحالات'!$B$2:$B$1001))-1),""),"")&IF(SUMPRODUCT(('تشخيص الحالات'!$B$2:$B$1001=B10)*('تشخيص الحالات'!$G$2:$G$1001=3))>0,"، "&IFERROR(INDEX('تشخيص الحالات'!$D$2:$D$1001,SUMPRODUCT(('تشخيص الحالات'!$B$2:$B$1001=B10)*('تشخيص الحالات'!$G$2:$G$1001=3)*ROW('تشخيص الحالات'!$B$2:$B$1001))-1),""),"")&IF(SUMPRODUCT(('تشخيص الحالات'!$B$2:$B$1001=B10)*('تشخيص الحالات'!$G$2:$G$1001=4))>0,"، "&IFERROR(INDEX('تشخيص الحالات'!$D$2:$D$1001,SUMPRODUCT(('تشخيص الحالات'!$B$2:$B$1001=B10)*('تشخيص الحالات'!$G$2:$G$1001=4)*ROW('تشخيص الحالات'!$B$2:$B$1001))-1),""),"")&IF(SUMPRODUCT(('تشخيص الحالات'!$B$2:$B$1001=B10)*('تشخيص الحالات'!$G$2:$G$1001=5))>0,"، "&IFERROR(INDEX('تشخيص الحالات'!$D$2:$D$1001,SUMPRODUCT(('تشخيص الحالات'!$B$2:$B$1001=B10)*('تشخيص الحالات'!$G$2:$G$1001=5)*ROW('تشخيص الحالات'!$B$2:$B$1001))-1),""),"")&IF(SUMPRODUCT(('تشخيص الحالات'!$B$2:$B$1001=B10)*('تشخيص الحالات'!$G$2:$G$1001=6))>0,"، "&IFERROR(INDEX('تشخيص الحالات'!$D$2:$D$1001,SUMPRODUCT(('تشخيص الحالات'!$B$2:$B$1001=B10)*('تشخيص الحالات'!$G$2:$G$1001=6)*ROW('تشخيص الحالات'!$B$2:$B$1001))-1),""),"")&IF(SUMPRODUCT(('تشخيص الحالات'!$B$2:$B$1001=B10)*('تشخيص الحالات'!$G$2:$G$1001=7))>0,"، "&IFERROR(INDEX('تشخيص الحالات'!$D$2:$D$1001,SUMPRODUCT(('تشخيص الحالات'!$B$2:$B$1001=B10)*('تشخيص الحالات'!$G$2:$G$1001=7)*ROW('تشخيص الحالات'!$B$2:$B$1001))-1),""),"")&IF(SUMPRODUCT(('تشخيص الحالات'!$B$2:$B$1001=B10)*('تشخيص الحالات'!$G$2:$G$1001=8))>0,"، "&IFERROR(INDEX('تشخيص الحالات'!$D$2:$D$1001,SUMPRODUCT(('تشخيص الحالات'!$B$2:$B$1001=B10)*('تشخيص الحالات'!$G$2:$G$1001=8)*ROW('تشخيص الحالات'!$B$2:$B$1001))-1),""),"") -> إعاقة بصرية، تأخر حركي | J10: 80 | K10: جلسات فردية | L10: 3500 | M10: شركة حديد | N10: 0 | O10: 3 | P10: 0 | Q10: 7 | R10: 0 | S10: 0 | T10: =SUM(tbl_Beneficiaries[[#This Row],[ التربية الخاصة ]:[ التأهيل النفسي الحركي ]]) -> 10
A11: 10 | B11: 1763354093 | C11: مستفيد10 | D11: ذكر | E11: 40726 | F11: مركز إرادة وتمكين للرعاية النهارية (القدس) | G11: مسائي | H11: 44963 | I11: =IFERROR(INDEX('تشخيص الحالات'!$D$2:$D$1001,SUMPRODUCT(('تشخيص الحالات'!$B$2:$B$1001=B11)*('تشخيص الحالات'!$G$2:$G$1001=1)*ROW('تشخيص الحالات'!$B$2:$B$1001))-1),"")&IF(SUMPRODUCT(('تشخيص الحالات'!$B$2:$B$1001=B11)*('تشخيص الحالات'!$G$2:$G$1001=2))>0,"، "&IFERROR(INDEX('تشخيص الحالات'!$D$2:$D$1001,SUMPRODUCT(('تشخيص الحالات'!$B$2:$B$1001=B11)*('تشخيص الحالات'!$G$2:$G$1001=2)*ROW('تشخيص الحالات'!$B$2:$B$1001))-1),""),"")&IF(SUMPRODUCT(('تشخيص الحالات'!$B$2:$B$1001=B11)*('تشخيص الحالات'!$G$2:$G$1001=3))>0,"، "&IFERROR(INDEX('تشخيص الحالات'!$D$2:$D$1001,SUMPRODUCT(('تشخيص الحالات'!$B$2:$B$1001=B11)*('تشخيص الحالات'!$G$2:$G$1001=3)*ROW('تشخيص الحالات'!$B$2:$B$1001))-1),""),"")&IF(SUMPRODUCT(('تشخيص الحالات'!$B$2:$B$1001=B11)*('تشخيص الحالات'!$G$2:$G$1001=4))>0,"، "&IFERROR(INDEX('تشخيص الحالات'!$D$2:$D$1001,SUMPRODUCT(('تشخيص الحالات'!$B$2:$B$1001=B11)*('تشخيص الحالات'!$G$2:$G$1001=4)*ROW('تشخيص الحالات'!$B$2:$B$1001))-1),""),"")&IF(SUMPRODUCT(('تشخيص الحالات'!$B$2:$B$1001=B11)*('تشخيص الحالات'!$G$2:$G$1001=5))>0,"، "&IFERROR(INDEX('تشخيص الحالات'!$D$2:$D$1001,SUMPRODUCT(('تشخيص الحالات'!$B$2:$B$1001=B11)*('تشخيص الحالات'!$G$2:$G$1001=5)*ROW('تشخيص الحالات'!$B$2:$B$1001))-1),""),"")&IF(SUMPRODUCT(('تشخيص الحالات'!$B$2:$B$1001=B11)*('تشخيص الحالات'!$G$2:$G$1001=6))>0,"، "&IFERROR(INDEX('تشخيص الحالات'!$D$2:$D$1001,SUMPRODUCT(('تشخيص الحالات'!$B$2:$B$1001=B11)*('تشخيص الحالات'!$G$2:$G$1001=6)*ROW('تشخيص الحالات'!$B$2:$B$1001))-1),""),"")&IF(SUMPRODUCT(('تشخيص الحالات'!$B$2:$B$1001=B11)*('تشخيص الحالات'!$G$2:$G$1001=7))>0,"، "&IFERROR(INDEX('تشخيص الحالات'!$D$2:$D$1001,SUMPRODUCT(('تشخيص الحالات'!$B$2:$B$1001=B11)*('تشخيص الحالات'!$G$2:$G$1001=7)*ROW('تشخيص الحالات'!$B$2:$B$1001))-1),""),"")&IF(SUMPRODUCT(('تشخيص الحالات'!$B$2:$B$1001=B11)*('تشخيص الحالات'!$G$2:$G$1001=8))>0,"، "&IFERROR(INDEX('تشخيص الحالات'!$D$2:$D$1001,SUMPRODUCT(('تشخيص الحالات'!$B$2:$B$1001=B11)*('تشخيص الحالات'!$G$2:$G$1001=8)*ROW('تشخيص الحالات'!$B$2:$B$1001))-1),""),"") -> اضطرابات سلوكية، تأخر نمائي، اضطراب نفسي حركي، متلازمة داون | J11: 105 | K11: فصول | L11: 1500 | M11: تأمين / شركات | N11: 0 | O11: 0 | P11: 0 | Q11: 8 | R11: 0 | S11: 0 | T11: =SUM(tbl_Beneficiaries[[#This Row],[ التربية الخاصة ]:[ التأهيل النفسي الحركي ]]) -> 8
A12: 11 | B12: 1231607400 | C12: مستفيد11 | D12: أنثى | E12: 40537 | F12: مركز إرادة وتمكين لمتلازمة داون (نجد) | G12: صباحي | H12: 45210 | I12: =IFERROR(INDEX('تشخيص الحالات'!$D$2:$D$1001,SUMPRODUCT(('تشخيص الحالات'!$B$2:$B$1001=B12)*('تشخيص الحالات'!$G$2:$G$1001=1)*ROW('تشخيص الحالات'!$B$2:$B$1001))-1),"")&IF(SUMPRODUCT(('تشخيص الحالات'!$B$2:$B$1001=B12)*('تشخيص الحالات'!$G$2:$G$1001=2))>0,"، "&IFERROR(INDEX('تشخيص الحالات'!$D$2:$D$1001,SUMPRODUCT(('تشخيص الحالات'!$B$2:$B$1001=B12)*('تشخيص الحالات'!$G$2:$G$1001=2)*ROW('تشخيص الحالات'!$B$2:$B$1001))-1),""),"")&IF(SUMPRODUCT(('تشخيص الحالات'!$B$2:$B$1001=B12)*('تشخيص الحالات'!$G$2:$G$1001=3))>0,"، "&IFERROR(INDEX('تشخيص الحالات'!$D$2:$D$1001,SUMPRODUCT(('تشخيص الحالات'!$B$2:$B$1001=B12)*('تشخيص الحالات'!$G$2:$G$1001=3)*ROW('تشخيص الحالات'!$B$2:$B$1001))-1),""),"")&IF(SUMPRODUCT(('تشخيص الحالات'!$B$2:$B$1001=B12)*('تشخيص الحالات'!$G$2:$G$1001=4))>0,"، "&IFERROR(INDEX('تشخيص الحالات'!$D$2:$D$1001,SUMPRODUCT(('تشخيص الحالات'!$B$2:$B$1001=B12)*('تشخيص الحالات'!$G$2:$G$1001=4)*ROW('تشخيص الحالات'!$B$2:$B$1001))-1),""),"")&IF(SUMPRODUCT(('تشخيص الحالات'!$B$2:$B$1001=B12)*('تشخيص الحالات'!$G$2:$G$1001=5))>0,"، "&IFERROR(INDEX('تشخيص الحالات'!$D$2:$D$1001,SUMPRODUCT(('تشخيص الحالات'!$B$2:$B$1001=B12)*('تشخيص الحالات'!$G$2:$G$1001=5)*ROW('تشخيص الحالات'!$B$2:$B$1001))-1),""),"")&IF(SUMPRODUCT(('تشخيص الحالات'!$B$2:$B$1001=B12)*('تشخيص الحالات'!$G$2:$G$1001=6))>0,"، "&IFERROR(INDEX('تشخيص الحالات'!$D$2:$D$1001,SUMPRODUCT(('تشخيص الحالات'!$B$2:$B$1001=B12)*('تشخيص الحالات'!$G$2:$G$1001=6)*ROW('تشخيص الحالات'!$B$2:$B$1001))-1),""),"")&IF(SUMPRODUCT(('تشخيص الحالات'!$B$2:$B$1001=B12)*('تشخيص الحالات'!$G$2:$G$1001=7))>0,"، "&IFERROR(INDEX('تشخيص الحالات'!$D$2:$D$1001,SUMPRODUCT(('تشخيص الحالات'!$B$2:$B$1001=B12)*('تشخيص الحالات'!$G$2:$G$1001=7)*ROW('تشخيص الحالات'!$B$2:$B$1001))-1),""),"")&IF(SUMPRODUCT(('تشخيص الحالات'!$B$2:$B$1001=B12)*('تشخيص الحالات'!$G$2:$G$1001=8))>0,"، "&IFERROR(INDEX('تشخيص الحالات'!$D$2:$D$1001,SUMPRODUCT(('تشخيص الحالات'!$B$2:$B$1001=B12)*('تشخيص الحالات'!$G$2:$G$1001=8)*ROW('تشخيص الحالات'!$B$2:$B$1001))-1),""),"") -> إعاقة ذهنية، اضطراب طيف التوحد | J12: 61 | K12: كلاهما | L12: 1500 | M12: شركة حديد | N12: 3 | O12: 6 | P12: 0 | Q12: 7 | R12: 5 | S12: 0 | T12: =SUM(tbl_Beneficiaries[[#This Row],[ التربية الخاصة ]:[ التأهيل النفسي الحركي ]]) -> 21
A13: 12 | B13: 1777789161 | C13: مستفيد12 | D13: أنثى | E13: 42840 | F13: مدرسة إرادة للتعليم (مكة) | G13: كلاهما | H13: 44820 | I13: =IFERROR(INDEX('تشخيص الحالات'!$D$2:$D$1001,SUMPRODUCT(('تشخيص الحالات'!$B$2:$B$1001=B13)*('تشخيص الحالات'!$G$2:$G$1001=1)*ROW('تشخيص الحالات'!$B$2:$B$1001))-1),"")&IF(SUMPRODUCT(('تشخيص الحالات'!$B$2:$B$1001=B13)*('تشخيص الحالات'!$G$2:$G$1001=2))>0,"، "&IFERROR(INDEX('تشخيص الحالات'!$D$2:$D$1001,SUMPRODUCT(('تشخيص الحالات'!$B$2:$B$1001=B13)*('تشخيص الحالات'!$G$2:$G$1001=2)*ROW('تشخيص الحالات'!$B$2:$B$1001))-1),""),"")&IF(SUMPRODUCT(('تشخيص الحالات'!$B$2:$B$1001=B13)*('تشخيص الحالات'!$G$2:$G$1001=3))>0,"، "&IFERROR(INDEX('تشخيص الحالات'!$D$2:$D$1001,SUMPRODUCT(('تشخيص الحالات'!$B$2:$B$1001=B13)*('تشخيص الحالات'!$G$2:$G$1001=3)*ROW('تشخيص الحالات'!$B$2:$B$1001))-1),""),"")&IF(SUMPRODUCT(('تشخيص الحالات'!$B$2:$B$1001=B13)*('تشخيص الحالات'!$G$2:$G$1001=4))>0,"، "&IFERROR(INDEX('تشخيص الحالات'!$D$2:$D$1001,SUMPRODUCT(('تشخيص الحالات'!$B$2:$B$1001=B13)*('تشخيص الحالات'!$G$2:$G$1001=4)*ROW('تشخيص الحالات'!$B$2:$B$1001))-1),""),"")&IF(SUMPRODUCT(('تشخيص الحالات'!$B$2:$B$1001=B13)*('تشخيص الحالات'!$G$2:$G$1001=5))>0,"، "&IFERROR(INDEX('تشخيص الحالات'!$D$2:$D$1001,SUMPRODUCT(('تشخيص الحالات'!$B$2:$B$1001=B13)*('تشخيص الحالات'!$G$2:$G$1001=5)*ROW('تشخيص الحالات'!$B$2:$B$1001))-1),""),"")&IF(SUMPRODUCT(('تشخيص الحالات'!$B$2:$B$1001=B13)*('تشخيص الحالات'!$G$2:$G$1001=6))>0,"، "&IFERROR(INDEX('تشخيص الحالات'!$D$2:$D$1001,SUMPRODUCT(('تشخيص الحالات'!$B$2:$B$1001=B13)*('تشخيص الحالات'!$G$2:$G$1001=6)*ROW('تشخيص الحالات'!$B$2:$B$1001))-1),""),"")&IF(SUMPRODUCT(('تشخيص الحالات'!$B$2:$B$1001=B13)*('تشخيص الحالات'!$G$2:$G$1001=7))>0,"، "&IFERROR(INDEX('تشخيص الحالات'!$D$2:$D$1001,SUMPRODUCT(('تشخيص الحالات'!$B$2:$B$1001=B13)*('تشخيص الحالات'!$G$2:$G$1001=7)*ROW('تشخيص الحالات'!$B$2:$B$1001))-1),""),"")&IF(SUMPRODUCT(('تشخيص الحالات'!$B$2:$B$1001=B13)*('تشخيص الحالات'!$G$2:$G$1001=8))>0,"، "&IFERROR(INDEX('تشخيص الحالات'!$D$2:$D$1001,SUMPRODUCT(('تشخيص الحالات'!$B$2:$B$1001=B13)*('تشخيص الحالات'!$G$2:$G$1001=8)*ROW('تشخيص الحالات'!$B$2:$B$1001))-1),""),"") -> تأخر نمائي، اضطراب نفسي حركي، صعوبات تعلم | J13: 91 | K13: فصول | L13: 3500 | M13: الشؤون الاجتماعية | N13: 1 | O13: 9 | P13: 0 | Q13: 8 | R13: 0 | S13: 1 | T13: =SUM(tbl_Beneficiaries[[#This Row],[ التربية الخاصة ]:[ التأهيل النفسي الحركي ]]) -> 19
A14: 13 | B14: 1239383239 | C14: مستفيد13 | D14: ذكر | E14: 41957 | F14: مركز إرادة وتمكين لرعاية ذوي الاحتياجات الخاصة (جلمودة) | G14: صباحي | H14: 45063 | I14: =IFERROR(INDEX('تشخيص الحالات'!$D$2:$D$1001,SUMPRODUCT(('تشخيص الحالات'!$B$2:$B$1001=B14)*('تشخيص الحالات'!$G$2:$G$1001=1)*ROW('تشخيص الحالات'!$B$2:$B$1001))-1),"")&IF(SUMPRODUCT(('تشخيص الحالات'!$B$2:$B$1001=B14)*('تشخيص الحالات'!$G$2:$G$1001=2))>0,"، "&IFERROR(INDEX('تشخيص الحالات'!$D$2:$D$1001,SUMPRODUCT(('تشخيص الحالات'!$B$2:$B$1001=B14)*('تشخيص الحالات'!$G$2:$G$1001=2)*ROW('تشخيص الحالات'!$B$2:$B$1001))-1),""),"")&IF(SUMPRODUCT(('تشخيص الحالات'!$B$2:$B$1001=B14)*('تشخيص الحالات'!$G$2:$G$1001=3))>0,"، "&IFERROR(INDEX('تشخيص الحالات'!$D$2:$D$1001,SUMPRODUCT(('تشخيص الحالات'!$B$2:$B$1001=B14)*('تشخيص الحالات'!$G$2:$G$1001=3)*ROW('تشخيص الحالات'!$B$2:$B$1001))-1),""),"")&IF(SUMPRODUCT(('تشخيص الحالات'!$B$2:$B$1001=B14)*('تشخيص الحالات'!$G$2:$G$1001=4))>0,"، "&IFERROR(INDEX('تشخيص الحالات'!$D$2:$D$1001,SUMPRODUCT(('تشخيص الحالات'!$B$2:$B$1001=B14)*('تشخيص الحالات'!$G$2:$G$1001=4)*ROW('تشخيص الحالات'!$B$2:$B$1001))-1),""),"")&IF(SUMPRODUCT(('تشخيص الحالات'!$B$2:$B$1001=B14)*('تشخيص الحالات'!$G$2:$G$1001=5))>0,"، "&IFERROR(INDEX('تشخيص الحالات'!$D$2:$D$1001,SUMPRODUCT(('تشخيص الحالات'!$B$2:$B$1001=B14)*('تشخيص الحالات'!$G$2:$G$1001=5)*ROW('تشخيص الحالات'!$B$2:$B$1001))-1),""),"")&IF(SUMPRODUCT(('تشخيص الحالات'!$B$2:$B$1001=B14)*('تشخيص الحالات'!$G$2:$G$1001=6))>0,"، "&IFERROR(INDEX('تشخيص الحالات'!$D$2:$D$1001,SUMPRODUCT(('تشخيص الحالات'!$B$2:$B$1001=B14)*('تشخيص الحالات'!$G$2:$G$1001=6)*ROW('تشخيص الحالات'!$B$2:$B$1001))-1),""),"")&IF(SUMPRODUCT(('تشخيص الحالات'!$B$2:$B$1001=B14)*('تشخيص الحالات'!$G$2:$G$1001=7))>0,"، "&IFERROR(INDEX('تشخيص الحالات'!$D$2:$D$1001,SUMPRODUCT(('تشخيص الحالات'!$B$2:$B$1001=B14)*('تشخيص الحالات'!$G$2:$G$1001=7)*ROW('تشخيص الحالات'!$B$2:$B$1001))-1),""),"")&IF(SUMPRODUCT(('تشخيص الحالات'!$B$2:$B$1001=B14)*('تشخيص الحالات'!$G$2:$G$1001=8))>0,"، "&IFERROR(INDEX('تشخيص الحالات'!$D$2:$D$1001,SUMPRODUCT(('تشخيص الحالات'!$B$2:$B$1001=B14)*('تشخيص الحالات'!$G$2:$G$1001=8)*ROW('تشخيص الحالات'!$B$2:$B$1001))-1),""),"") -> تأخر حركي، إعاقة بصرية | J14: 54 | K14: فصول | L14: 2000 | M14: أفراد | N14: 5 | O14: 6 | P14: 0 | Q14: 0 | R14: 0 | S14: 8 | T14: =SUM(tbl_Beneficiaries[[#This Row],[ التربية الخاصة ]:[ التأهيل النفسي الحركي ]]) -> 19
... A201: 200 | B201: 1358470403 | C201: مستفيد200 | D201: ذكر | E201: 40556 | F201: مركز إرادة وتمكين للرعاية النهارية (القدس) | G201: مسائي | H201: 44806 | I201: =IFERROR(INDEX('تشخيص الحالات'!$D$2:$D$1001,SUMPRODUCT(('تشخيص الحالات'!$B$2:$B$1001=B201)*('تشخيص الحالات'!$G$2:$G$1001=1)*ROW('تشخيص الحالات'!$B$2:$B$1001))-1),"")&IF(SUMPRODUCT(('تشخيص الحالات'!$B$2:$B$1001=B201)*('تشخيص الحالات'!$G$2:$G$1001=2))>0,"، "&IFERROR(INDEX('تشخيص الحالات'!$D$2:$D$1001,SUMPRODUCT(('تشخيص الحالات'!$B$2:$B$1001=B201)*('تشخيص الحالات'!$G$2:$G$1001=2)*ROW('تشخيص الحالات'!$B$2:$B$1001))-1),""),"")&IF(SUMPRODUCT(('تشخيص الحالات'!$B$2:$B$1001=B201)*('تشخيص الحالات'!$G$2:$G$1001=3))>0,"، "&IFERROR(INDEX('تشخيص الحالات'!$D$2:$D$1001,SUMPRODUCT(('تشخيص الحالات'!$B$2:$B$1001=B201)*('تشخيص الحالات'!$G$2:$G$1001=3)*ROW('تشخيص الحالات'!$B$2:$B$1001))-1),""),"")&IF(SUMPRODUCT(('تشخيص الحالات'!$B$2:$B$1001=B201)*('تشخيص الحالات'!$G$2:$G$1001=4))>0,"، "&IFERROR(INDEX('تشخيص الحالات'!$D$2:$D$1001,SUMPRODUCT(('تشخيص الحالات'!$B$2:$B$1001=B201)*('تشخيص الحالات'!$G$2:$G$1001=4)*ROW('تشخيص الحالات'!$B$2:$B$1001))-1),""),"")&IF(SUMPRODUCT(('تشخيص الحالات'!$B$2:$B$1001=B201)*('تشخيص الحالات'!$G$2:$G$1001=5))>0,"، "&IFERROR(INDEX('تشخيص الحالات'!$D$2:$D$1001,SUMPRODUCT(('تشخيص الحالات'!$B$2:$B$1001=B201)*('تشخيص الحالات'!$G$2:$G$1001=5)*ROW('تشخيص الحالات'!$B$2:$B$1001))-1),""),"")&IF(SUMPRODUCT(('تشخيص الحالات'!$B$2:$B$1001=B201)*('تشخيص الحالات'!$G$2:$G$1001=6))>0,"، "&IFERROR(INDEX('تشخيص الحالات'!$D$2:$D$1001,SUMPRODUCT(('تشخيص الحالات'!$B$2:$B$1001=B201)*('تشخيص الحالات'!$G$2:$G$1001=6)*ROW('تشخيص الحالات'!$B$2:$B$1001))-1),""),"")&IF(SUMPRODUCT(('تشخيص الحالات'!$B$2:$B$1001=B201)*('تشخيص الحالات'!$G$2:$G$1001=7))>0,"، "&IFERROR(INDEX('تشخيص الحالات'!$D$2:$D$1001,SUMPRODUCT(('تشخيص الحالات'!$B$2:$B$1001=B201)*('تشخيص الحالات'!$G$2:$G$1001=7)*ROW('تشخيص الحالات'!$B$2:$B$1001))-1),""),"")&IF(SUMPRODUCT(('تشخيص الحالات'!$B$2:$B$1001=B201)*('تشخيص الحالات'!$G$2:$G$1001=8))>0,"، "&IFERROR(INDEX('تشخيص الحالات'!$D$2:$D$1001,SUMPRODUCT(('تشخيص الحالات'!$B$2:$B$1001=B201)*('تشخيص الحالات'!$G$2:$G$1001=8)*ROW('تشخيص الحالات'!$B$2:$B$1001))-1),""),"") -> تأخر نمائي، إعاقة ذهنية، اضطراب نفسي حركي، إعاقة سمعية | J201: 96 | K201: فصول | L201: 1500 | M201: شركة حديد | N201: 3 | O201: 0 | P201: 3 | Q201: 9 | R201: 7 | S201: 5 | T201: =SUM(tbl_Beneficiaries[[#This Row],[ التربية الخاصة ]:[ التأهيل النفسي الحركي ]]) -> 27
I202: =IFERROR(INDEX('تشخيص الحالات'!$D$2:$D$1001,SUMPRODUCT(('تشخيص الحالات'!$B$2:$B$1001=B202)*('تشخيص الحالات'!$G$2:$G$1001=1)*ROW('تشخيص الحالات'!$B$2:$B$1001))-1),"")&IF(SUMPRODUCT(('تشخيص الحالات'!$B$2:$B$1001=B202)*('تشخيص الحالات'!$G$2:$G$1001=2))>0,"، "&IFERROR(INDEX('تشخيص الحالات'!$D$2:$D$1001,SUMPRODUCT(('تشخيص الحالات'!$B$2:$B$1001=B202)*('تشخيص الحالات'!$G$2:$G$1001=2)*ROW('تشخيص الحالات'!$B$2:$B$1001))-1),""),"")&IF(SUMPRODUCT(('تشخيص الحالات'!$B$2:$B$1001=B202)*('تشخيص الحالات'!$G$2:$G$1001=3))>0,"، "&IFERROR(INDEX('تشخيص الحالات'!$D$2:$D$1001,SUMPRODUCT(('تشخيص الحالات'!$B$2:$B$1001=B202)*('تشخيص الحالات'!$G$2:$G$1001=3)*ROW('تشخيص الحالات'!$B$2:$B$1001))-1),""),"")&IF(SUMPRODUCT(('تشخيص الحالات'!$B$2:$B$1001=B202)*('تشخيص الحالات'!$G$2:$G$1001=4))>0,"، "&IFERROR(INDEX('تشخيص الحالات'!$D$2:$D$1001,SUMPRODUCT(('تشخيص الحالات'!$B$2:$B$1001=B202)*('تشخيص الحالات'!$G$2:$G$1001=4)*ROW('تشخيص الحالات'!$B$2:$B$1001))-1),""),"")&IF(SUMPRODUCT(('تشخيص الحالات'!$B$2:$B$1001=B202)*('تشخيص الحالات'!$G$2:$G$1001=5))>0,"، "&IFERROR(INDEX('تشخيص الحالات'!$D$2:$D$1001,SUMPRODUCT(('تشخيص الحالات'!$B$2:$B$1001=B202)*('تشخيص الحالات'!$G$2:$G$1001=5)*ROW('تشخيص الحالات'!$B$2:$B$1001))-1),""),"")&IF(SUMPRODUCT(('تشخيص الحالات'!$B$2:$B$1001=B202)*('تشخيص الحالات'!$G$2:$G$1001=6))>0,"، "&IFERROR(INDEX('تشخيص الحالات'!$D$2:$D$1001,SUMPRODUCT(('تشخيص الحالات'!$B$2:$B$1001=B202)*('تشخيص الحالات'!$G$2:$G$1001=6)*ROW('تشخيص الحالات'!$B$2:$B$1001))-1),""),"")&IF(SUMPRODUCT(('تشخيص الحالات'!$B$2:$B$1001=B202)*('تشخيص الحالات'!$G$2:$G$1001=7))>0,"، "&IFERROR(INDEX('تشخيص الحالات'!$D$2:$D$1001,SUMPRODUCT(('تشخيص الحالات'!$B$2:$B$1001=B202)*('تشخيص الحالات'!$G$2:$G$1001=7)*ROW('تشخيص الحالات'!$B$2:$B$1001))-1),""),"")&IF(SUMPRODUCT(('تشخيص الحالات'!$B$2:$B$1001=B202)*('تشخيص الحالات'!$G$2:$G$1001=8))>0,"، "&IFERROR(INDEX('تشخيص الحالات'!$D$2:$D$1001,SUMPRODUCT(('تشخيص الحالات'!$B$2:$B$1001=B202)*('تشخيص الحالات'!$G$2:$G$1001=8)*ROW('تشخيص الحالات'!$B$2:$B$1001))-1),""),"")
I203: =IFERROR(INDEX('تشخيص الحالات'!$D$2:$D$1001,SUMPRODUCT(('تشخيص الحالات'!$B$2:$B$1001=B203)*('تشخيص الحالات'!$G$2:$G$1001=1)*ROW('تشخيص الحالات'!$B$2:$B$1001))-1),"")&IF(SUMPRODUCT(('تشخيص الحالات'!$B$2:$B$1001=B203)*('تشخيص الحالات'!$G$2:$G$1001=2))>0,"، "&IFERROR(INDEX('تشخيص الحالات'!$D$2:$D$1001,SUMPRODUCT(('تشخيص الحالات'!$B$2:$B$1001=B203)*('تشخيص الحالات'!$G$2:$G$1001=2)*ROW('تشخيص الحالات'!$B$2:$B$1001))-1),""),"")&IF(SUMPRODUCT(('تشخيص الحالات'!$B$2:$B$1001=B203)*('تشخيص الحالات'!$G$2:$G$1001=3))>0,"، "&IFERROR(INDEX('تشخيص الحالات'!$D$2:$D$1001,SUMPRODUCT(('تشخيص الحالات'!$B$2:$B$1001=B203)*('تشخيص الحالات'!$G$2:$G$1001=3)*ROW('تشخيص الحالات'!$B$2:$B$1001))-1),""),"")&IF(SUMPRODUCT(('تشخيص الحالات'!$B$2:$B$1001=B203)*('تشخيص الحالات'!$G$2:$G$1001=4))>0,"، "&IFERROR(INDEX('تشخيص الحالات'!$D$2:$D$1001,SUMPRODUCT(('تشخيص الحالات'!$B$2:$B$1001=B203)*('تشخيص الحالات'!$G$2:$G$1001=4)*ROW('تشخيص الحالات'!$B$2:$B$1001))-1),""),"")&IF(SUMPRODUCT(('تشخيص الحالات'!$B$2:$B$1001=B203)*('تشخيص الحالات'!$G$2:$G$1001=5))>0,"، "&IFERROR(INDEX('تشخيص الحالات'!$D$2:$D$1001,SUMPRODUCT(('تشخيص الحالات'!$B$2:$B$1001=B203)*('تشخيص الحالات'!$G$2:$G$1001=5)*ROW('تشخيص الحالات'!$B$2:$B$1001))-1),""),"")&IF(SUMPRODUCT(('تشخيص الحالات'!$B$2:$B$1001=B203)*('تشخيص الحالات'!$G$2:$G$1001=6))>0,"، "&IFERROR(INDEX('تشخيص الحالات'!$D$2:$D$1001,SUMPRODUCT(('تشخيص الحالات'!$B$2:$B$1001=B203)*('تشخيص الحالات'!$G$2:$G$1001=6)*ROW('تشخيص الحالات'!$B$2:$B$1001))-1),""),"")&IF(SUMPRODUCT(('تشخيص الحالات'!$B$2:$B$1001=B203)*('تشخيص الحالات'!$G$2:$G$1001=7))>0,"، "&IFERROR(INDEX('تشخيص الحالات'!$D$2:$D$1001,SUMPRODUCT(('تشخيص الحالات'!$B$2:$B$1001=B203)*('تشخيص الحالات'!$G$2:$G$1001=7)*ROW('تشخيص الحالات'!$B$2:$B$1001))-1),""),"")&IF(SUMPRODUCT(('تشخيص الحالات'!$B$2:$B$1001=B203)*('تشخيص الحالات'!$G$2:$G$1001=8))>0,"، "&IFERROR(INDEX('تشخيص الحالات'!$D$2:$D$1001,SUMPRODUCT(('تشخيص الحالات'!$B$2:$B$1001=B203)*('تشخيص الحالات'!$G$2:$G$1001=8)*ROW('تشخيص الحالات'!$B$2:$B$1001))-1),""),"")
I204: =IFERROR(INDEX('تشخيص الحالات'!$D$2:$D$1001,SUMPRODUCT(('تشخيص الحالات'!$B$2:$B$1001=B204)*('تشخيص الحالات'!$G$2:$G$1001=1)*ROW('تشخيص الحالات'!$B$2:$B$1001))-1),"")&IF(SUMPRODUCT(('تشخيص الحالات'!$B$2:$B$1001=B204)*('تشخيص الحالات'!$G$2:$G$1001=2))>0,"، "&IFERROR(INDEX('تشخيص الحالات'!$D$2:$D$1001,SUMPRODUCT(('تشخيص الحالات'!$B$2:$B$1001=B204)*('تشخيص الحالات'!$G$2:$G$1001=2)*ROW('تشخيص الحالات'!$B$2:$B$1001))-1),""),"")&IF(SUMPRODUCT(('تشخيص الحالات'!$B$2:$B$1001=B204)*('تشخيص الحالات'!$G$2:$G$1001=3))>0,"، "&IFERROR(INDEX('تشخيص الحالات'!$D$2:$D$1001,SUMPRODUCT(('تشخيص الحالات'!$B$2:$B$1001=B204)*('تشخيص الحالات'!$G$2:$G$1001=3)*ROW('تشخيص الحالات'!$B$2:$B$1001))-1),""),"")&IF(SUMPRODUCT(('تشخيص الحالات'!$B$2:$B$1001=B204)*('تشخيص الحالات'!$G$2:$G$1001=4))>0,"، "&IFERROR(INDEX('تشخيص الحالات'!$D$2:$D$1001,SUMPRODUCT(('تشخيص الحالات'!$B$2:$B$1001=B204)*('تشخيص الحالات'!$G$2:$G$1001=4)*ROW('تشخيص الحالات'!$B$2:$B$1001))-1),""),"")&IF(SUMPRODUCT(('تشخيص الحالات'!$B$2:$B$1001=B204)*('تشخيص الحالات'!$G$2:$G$1001=5))>0,"، "&IFERROR(INDEX('تشخيص الحالات'!$D$2:$D$1001,SUMPRODUCT(('تشخيص الحالات'!$B$2:$B$1001=B204)*('تشخيص الحالات'!$G$2:$G$1001=5)*ROW('تشخيص الحالات'!$B$2:$B$1001))-1),""),"")&IF(SUMPRODUCT(('تشخيص الحالات'!$B$2:$B$1001=B204)*('تشخيص الحالات'!$G$2:$G$1001=6))>0,"، "&IFERROR(INDEX('تشخيص الحالات'!$D$2:$D$1001,SUMPRODUCT(('تشخيص الحالات'!$B$2:$B$1001=B204)*('تشخيص الحالات'!$G$2:$G$1001=6)*ROW('تشخيص الحالات'!$B$2:$B$1001))-1),""),"")&IF(SUMPRODUCT(('تشخيص الحالات'!$B$2:$B$1001=B204)*('تشخيص الحالات'!$G$2:$G$1001=7))>0,"، "&IFERROR(INDEX('تشخيص الحالات'!$D$2:$D$1001,SUMPRODUCT(('تشخيص الحالات'!$B$2:$B$1001=B204)*('تشخيص الحالات'!$G$2:$G$1001=7)*ROW('تشخيص الحالات'!$B$2:$B$1001))-1),""),"")&IF(SUMPRODUCT(('تشخيص الحالات'!$B$2:$B$1001=B204)*('تشخيص الحالات'!$G$2:$G$1001=8))>0,"، "&IFERROR(INDEX('تشخيص الحالات'!$D$2:$D$1001,SUMPRODUCT(('تشخيص الحالات'!$B$2:$B$1001=B204)*('تشخيص الحالات'!$G$2:$G$1001=8)*ROW('تشخيص الحالات'!$B$2:$B$1001))-1),""),"")
I205: =IFERROR(INDEX('تشخيص الحالات'!$D$2:$D$1001,SUMPRODUCT(('تشخيص الحالات'!$B$2:$B$1001=B205)*('تشخيص الحالات'!$G$2:$G$1001=1)*ROW('تشخيص الحالات'!$B$2:$B$1001))-1),"")&IF(SUMPRODUCT(('تشخيص الحالات'!$B$2:$B$1001=B205)*('تشخيص الحالات'!$G$2:$G$1001=2))>0,"، "&IFERROR(INDEX('تشخيص الحالات'!$D$2:$D$1001,SUMPRODUCT(('تشخيص الحالات'!$B$2:$B$1001=B205)*('تشخيص الحالات'!$G$2:$G$1001=2)*ROW('تشخيص الحالات'!$B$2:$B$1001))-1),""),"")&IF(SUMPRODUCT(('تشخيص الحالات'!$B$2:$B$1001=B205)*('تشخيص الحالات'!$G$2:$G$1001=3))>0,"، "&IFERROR(INDEX('تشخيص الحالات'!$D$2:$D$1001,SUMPRODUCT(('تشخيص الحالات'!$B$2:$B$1001=B205)*('تشخيص الحالات'!$G$2:$G$1001=3)*ROW('تشخيص الحالات'!$B$2:$B$1001))-1),""),"")&IF(SUMPRODUCT(('تشخيص الحالات'!$B$2:$B$1001=B205)*('تشخيص الحالات'!$G$2:$G$1001=4))>0,"، "&IFERROR(INDEX('تشخيص الحالات'!$D$2:$D$1001,SUMPRODUCT(('تشخيص الحالات'!$B$2:$B$1001=B205)*('تشخيص الحالات'!$G$2:$G$1001=4)*ROW('تشخيص الحالات'!$B$2:$B$1001))-1),""),"")&IF(SUMPRODUCT(('تشخيص الحالات'!$B$2:$B$1001=B205)*('تشخيص الحالات'!$G$2:$G$1001=5))>0,"، "&IFERROR(INDEX('تشخيص الحالات'!$D$2:$D$1001,SUMPRODUCT(('تشخيص الحالات'!$B$2:$B$1001=B205)*('تشخيص الحالات'!$G$2:$G$1001=5)*ROW('تشخيص الحالات'!$B$2:$B$1001))-1),""),"")&IF(SUMPRODUCT(('تشخيص الحالات'!$B$2:$B$1001=B205)*('تشخيص الحالات'!$G$2:$G$1001=6))>0,"، "&IFERROR(INDEX('تشخيص الحالات'!$D$2:$D$1001,SUMPRODUCT(('تشخيص الحالات'!$B$2:$B$1001=B205)*('تشخيص الحالات'!$G$2:$G$1001=6)*ROW('تشخيص الحالات'!$B$2:$B$1001))-1),""),"")&IF(SUMPRODUCT(('تشخيص الحالات'!$B$2:$B$1001=B205)*('تشخيص الحالات'!$G$2:$G$1001=7))>0,"، "&IFERROR(INDEX('تشخيص الحالات'!$D$2:$D$1001,SUMPRODUCT(('تشخيص الحالات'!$B$2:$B$1001=B205)*('تشخيص الحالات'!$G$2:$G$1001=7)*ROW('تشخيص الحالات'!$B$2:$B$1001))-1),""),"")&IF(SUMPRODUCT(('تشخيص الحالات'!$B$2:$B$1001=B205)*('تشخيص الحالات'!$G$2:$G$1001=8))>0,"، "&IFERROR(INDEX('تشخيص الحالات'!$D$2:$D$1001,SUMPRODUCT(('تشخيص الحالات'!$B$2:$B$1001=B205)*('تشخيص الحالات'!$G$2:$G$1001=8)*ROW('تشخيص الحالات'!$B$2:$B$1001))-1),""),"")
I206: =IFERROR(INDEX('تشخيص الحالات'!$D$2:$D$1001,SUMPRODUCT(('تشخيص الحالات'!$B$2:$B$1001=B206)*('تشخيص الحالات'!$G$2:$G$1001=1)*ROW('تشخيص الحالات'!$B$2:$B$1001))-1),"")&IF(SUMPRODUCT(('تشخيص الحالات'!$B$2:$B$1001=B206)*('تشخيص الحالات'!$G$2:$G$1001=2))>0,"، "&IFERROR(INDEX('تشخيص الحالات'!$D$2:$D$1001,SUMPRODUCT(('تشخيص الحالات'!$B$2:$B$1001=B206)*('تشخيص الحالات'!$G$2:$G$1001=2)*ROW('تشخيص الحالات'!$B$2:$B$1001))-1),""),"")&IF(SUMPRODUCT(('تشخيص الحالات'!$B$2:$B$1001=B206)*('تشخيص الحالات'!$G$2:$G$1001=3))>0,"، "&IFERROR(INDEX('تشخيص الحالات'!$D$2:$D$1001,SUMPRODUCT(('تشخيص الحالات'!$B$2:$B$1001=B206)*('تشخيص الحالات'!$G$2:$G$1001=3)*ROW('تشخيص الحالات'!$B$2:$B$1001))-1),""),"")&IF(SUMPRODUCT(('تشخيص الحالات'!$B$2:$B$1001=B206)*('تشخيص الحالات'!$G$2:$G$1001=4))>0,"، "&IFERROR(INDEX('تشخيص الحالات'!$D$2:$D$1001,SUMPRODUCT(('تشخيص الحالات'!$B$2:$B$1001=B206)*('تشخيص الحالات'!$G$2:$G$1001=4)*ROW('تشخيص الحالات'!$B$2:$B$1001))-1),""),"")&IF(SUMPRODUCT(('تشخيص الحالات'!$B$2:$B$1001=B206)*('تشخيص الحالات'!$G$2:$G$1001=5))>0,"، "&IFERROR(INDEX('تشخيص الحالات'!$D$2:$D$1001,SUMPRODUCT(('تشخيص الحالات'!$B$2:$B$1001=B206)*('تشخيص الحالات'!$G$2:$G$1001=5)*ROW('تشخيص الحالات'!$B$2:$B$1001))-1),""),"")&IF(SUMPRODUCT(('تشخيص الحالات'!$B$2:$B$1001=B206)*('تشخيص الحالات'!$G$2:$G$1001=6))>0,"، "&IFERROR(INDEX('تشخيص الحالات'!$D$2:$D$1001,SUMPRODUCT(('تشخيص الحالات'!$B$2:$B$1001=B206)*('تشخيص الحالات'!$G$2:$G$1001=6)*ROW('تشخيص الحالات'!$B$2:$B$1001))-1),""),"")&IF(SUMPRODUCT(('تشخيص الحالات'!$B$2:$B$1001=B206)*('تشخيص الحالات'!$G$2:$G$1001=7))>0,"، "&IFERROR(INDEX('تشخيص الحالات'!$D$2:$D$1001,SUMPRODUCT(('تشخيص الحالات'!$B$2:$B$1001=B206)*('تشخيص الحالات'!$G$2:$G$1001=7)*ROW('تشخيص الحالات'!$B$2:$B$1001))-1),""),"")&IF(SUMPRODUCT(('تشخيص الحالات'!$B$2:$B$1001=B206)*('تشخيص الحالات'!$G$2:$G$1001=8))>0,"، "&IFERROR(INDEX('تشخيص الحالات'!$D$2:$D$1001,SUMPRODUCT(('تشخيص الحالات'!$B$2:$B$1001=B206)*('تشخيص الحالات'!$G$2:$G$1001=8)*ROW('تشخيص الحالات'!$B$2:$B$1001))-1),""),"")
I207: =IFERROR(INDEX('تشخيص الحالات'!$D$2:$D$1001,SUMPRODUCT(('تشخيص الحالات'!$B$2:$B$1001=B207)*('تشخيص الحالات'!$G$2:$G$1001=1)*ROW('تشخيص الحالات'!$B$2:$B$1001))-1),"")&IF(SUMPRODUCT(('تشخيص الحالات'!$B$2:$B$1001=B207)*('تشخيص الحالات'!$G$2:$G$1001=2))>0,"، "&IFERROR(INDEX('تشخيص الحالات'!$D$2:$D$1001,SUMPRODUCT(('تشخيص الحالات'!$B$2:$B$1001=B207)*('تشخيص الحالات'!$G$2:$G$1001=2)*ROW('تشخيص الحالات'!$B$2:$B$1001))-1),""),"")&IF(SUMPRODUCT(('تشخيص الحالات'!$B$2:$B$1001=B207)*('تشخيص الحالات'!$G$2:$G$1001=3))>0,"، "&IFERROR(INDEX('تشخيص الحالات'!$D$2:$D$1001,SUMPRODUCT(('تشخيص الحالات'!$B$2:$B$1001=B207)*('تشخيص الحالات'!$G$2:$G$1001=3)*ROW('تشخيص الحالات'!$B$2:$B$1001))-1),""),"")&IF(SUMPRODUCT(('تشخيص الحالات'!$B$2:$B$1001=B207)*('تشخيص الحالات'!$G$2:$G$1001=4))>0,"، "&IFERROR(INDEX('تشخيص الحالات'!$D$2:$D$1001,SUMPRODUCT(('تشخيص الحالات'!$B$2:$B$1001=B207)*('تشخيص الحالات'!$G$2:$G$1001=4)*ROW('تشخيص الحالات'!$B$2:$B$1001))-1),""),"")&IF(SUMPRODUCT(('تشخيص الحالات'!$B$2:$B$1001=B207)*('تشخيص الحالات'!$G$2:$G$1001=5))>0,"، "&IFERROR(INDEX('تشخيص الحالات'!$D$2:$D$1001,SUMPRODUCT(('تشخيص الحالات'!$B$2:$B$1001=B207)*('تشخيص الحالات'!$G$2:$G$1001=5)*ROW('تشخيص الحالات'!$B$2:$B$1001))-1),""),"")&IF(SUMPRODUCT(('تشخيص الحالات'!$B$2:$B$1001=B207)*('تشخيص الحالات'!$G$2:$G$1001=6))>0,"، "&IFERROR(INDEX('تشخيص الحالات'!$D$2:$D$1001,SUMPRODUCT(('تشخيص الحالات'!$B$2:$B$1001=B207)*('تشخيص الحالات'!$G$2:$G$1001=6)*ROW('تشخيص الحالات'!$B$2:$B$1001))-1),""),"")&IF(SUMPRODUCT(('تشخيص الحالات'!$B$2:$B$1001=B207)*('تشخيص الحالات'!$G$2:$G$1001=7))>0,"، "&IFERROR(INDEX('تشخيص الحالات'!$D$2:$D$1001,SUMPRODUCT(('تشخيص الحالات'!$B$2:$B$1001=B207)*('تشخيص الحالات'!$G$2:$G$1001=7)*ROW('تشخيص الحالات'!$B$2:$B$1001))-1),""),"")&IF(SUMPRODUCT(('تشخيص الحالات'!$B$2:$B$1001=B207)*('تشخيص الحالات'!$G$2:$G$1001=8))>0,"، "&IFERROR(INDEX('تشخيص الحالات'!$D$2:$D$1001,SUMPRODUCT(('تشخيص الحالات'!$B$2:$B$1001=B207)*('تشخيص الحالات'!$G$2:$G$1001=8)*ROW('تشخيص الحالات'!$B$2:$B$1001))-1),""),"")
I208: =IFERROR(INDEX('تشخيص الحالات'!$D$2:$D$1001,SUMPRODUCT(('تشخيص الحالات'!$B$2:$B$1001=B208)*('تشخيص الحالات'!$G$2:$G$1001=1)*ROW('تشخيص الحالات'!$B$2:$B$1001))-1),"")&IF(SUMPRODUCT(('تشخيص الحالات'!$B$2:$B$1001=B208)*('تشخيص الحالات'!$G$2:$G$1001=2))>0,"، "&IFERROR(INDEX('تشخيص الحالات'!$D$2:$D$1001,SUMPRODUCT(('تشخيص الحالات'!$B$2:$B$1001=B208)*('تشخيص الحالات'!$G$2:$G$1001=2)*ROW('تشخيص الحالات'!$B$2:$B$1001))-1),""),"")&IF(SUMPRODUCT(('تشخيص الحالات'!$B$2:$B$1001=B208)*('تشخيص الحالات'!$G$2:$G$1001=3))>0,"، "&IFERROR(INDEX('تشخيص الحالات'!$D$2:$D$1001,SUMPRODUCT(('تشخيص الحالات'!$B$2:$B$1001=B208)*('تشخيص الحالات'!$G$2:$G$1001=3)*ROW('تشخيص الحالات'!$B$2:$B$1001))-1),""),"")&IF(SUMPRODUCT(('تشخيص الحالات'!$B$2:$B$1001=B208)*('تشخيص الحالات'!$G$2:$G$1001=4))>0,"، "&IFERROR(INDEX('تشخيص الحالات'!$D$2:$D$1001,SUMPRODUCT(('تشخيص الحالات'!$B$2:$B$1001=B208)*('تشخيص الحالات'!$G$2:$G$1001=4)*ROW('تشخيص الحالات'!$B$2:$B$1001))-1),""),"")&IF(SUMPRODUCT(('تشخيص الحالات'!$B$2:$B$1001=B208)*('تشخيص الحالات'!$G$2:$G$1001=5))>0,"، "&IFERROR(INDEX('تشخيص الحالات'!$D$2:$D$1001,SUMPRODUCT(('تشخيص الحالات'!$B$2:$B$1001=B208)*('تشخيص الحالات'!$G$2:$G$1001=5)*ROW('تشخيص الحالات'!$B$2:$B$1001))-1),""),"")&IF(SUMPRODUCT(('تشخيص الحالات'!$B$2:$B$1001=B208)*('تشخيص الحالات'!$G$2:$G$1001=6))>0,"، "&IFERROR(INDEX('تشخيص الحالات'!$D$2:$D$1001,SUMPRODUCT(('تشخيص الحالات'!$B$2:$B$1001=B208)*('تشخيص الحالات'!$G$2:$G$1001=6)*ROW('تشخيص الحالات'!$B$2:$B$1001))-1),""),"")&IF(SUMPRODUCT(('تشخيص الحالات'!$B$2:$B$1001=B208)*('تشخيص الحالات'!$G$2:$G$1001=7))>0,"، "&IFERROR(INDEX('تشخيص الحالات'!$D$2:$D$1001,SUMPRODUCT(('تشخيص الحالات'!$B$2:$B$1001=B208)*('تشخيص الحالات'!$G$2:$G$1001=7)*ROW('تشخيص الحالات'!$B$2:$B$1001))-1),""),"")&IF(SUMPRODUCT(('تشخيص الحالات'!$B$2:$B$1001=B208)*('تشخيص الحالات'!$G$2:$G$1001=8))>0,"، "&IFERROR(INDEX('تشخيص الحالات'!$D$2:$D$1001,SUMPRODUCT(('تشخيص الحالات'!$B$2:$B$1001=B208)*('تشخيص الحالات'!$G$2:$G$1001=8)*ROW('تشخيص الحالات'!$B$2:$B$1001))-1),""),"")
I209: =IFERROR(INDEX('تشخيص الحالات'!$D$2:$D$1001,SUMPRODUCT(('تشخيص الحالات'!$B$2:$B$1001=B209)*('تشخيص الحالات'!$G$2:$G$1001=1)*ROW('تشخيص الحالات'!$B$2:$B$1001))-1),"")&IF(SUMPRODUCT(('تشخيص الحالات'!$B$2:$B$1001=B209)*('تشخيص الحالات'!$G$2:$G$1001=2))>0,"، "&IFERROR(INDEX('تشخيص الحالات'!$D$2:$D$1001,SUMPRODUCT(('تشخيص الحالات'!$B$2:$B$1001=B209)*('تشخيص الحالات'!$G$2:$G$1001=2)*ROW('تشخيص الحالات'!$B$2:$B$1001))-1),""),"")&IF(SUMPRODUCT(('تشخيص الحالات'!$B$2:$B$1001=B209)*('تشخيص الحالات'!$G$2:$G$1001=3))>0,"، "&IFERROR(INDEX('تشخيص الحالات'!$D$2:$D$1001,SUMPRODUCT(('تشخيص الحالات'!$B$2:$B$1001=B209)*('تشخيص الحالات'!$G$2:$G$1001=3)*ROW('تشخيص الحالات'!$B$2:$B$1001))-1),""),"")&IF(SUMPRODUCT(('تشخيص الحالات'!$B$2:$B$1001=B209)*('تشخيص الحالات'!$G$2:$G$1001=4))>0,"، "&IFERROR(INDEX('تشخيص الحالات'!$D$2:$D$1001,SUMPRODUCT(('تشخيص الحالات'!$B$2:$B$1001=B209)*('تشخيص الحالات'!$G$2:$G$1001=4)*ROW('تشخيص الحالات'!$B$2:$B$1001))-1),""),"")&IF(SUMPRODUCT(('تشخيص الحالات'!$B$2:$B$1001=B209)*('تشخيص الحالات'!$G$2:$G$1001=5))>0,"، "&IFERROR(INDEX('تشخيص الحالات'!$D$2:$D$1001,SUMPRODUCT(('تشخيص الحالات'!$B$2:$B$1001=B209)*('تشخيص الحالات'!$G$2:$G$1001=5)*ROW('تشخيص الحالات'!$B$2:$B$1001))-1),""),"")&IF(SUMPRODUCT(('تشخيص الحالات'!$B$2:$B$1001=B209)*('تشخيص الحالات'!$G$2:$G$1001=6))>0,"، "&IFERROR(INDEX('تشخيص الحالات'!$D$2:$D$1001,SUMPRODUCT(('تشخيص الحالات'!$B$2:$B$1001=B209)*('تشخيص الحالات'!$G$2:$G$1001=6)*ROW('تشخيص الحالات'!$B$2:$B$1001))-1),""),"")&IF(SUMPRODUCT(('تشخيص الحالات'!$B$2:$B$1001=B209)*('تشخيص الحالات'!$G$2:$G$1001=7))>0,"، "&IFERROR(INDEX('تشخيص الحالات'!$D$2:$D$1001,SUMPRODUCT(('تشخيص الحالات'!$B$2:$B$1001=B209)*('تشخيص الحالات'!$G$2:$G$1001=7)*ROW('تشخيص الحالات'!$B$2:$B$1001))-1),""),"")&IF(SUMPRODUCT(('تشخيص الحالات'!$B$2:$B$1001=B209)*('تشخيص الحالات'!$G$2:$G$1001=8))>0,"، "&IFERROR(INDEX('تشخيص الحالات'!$D$2:$D$1001,SUMPRODUCT(('تشخيص الحالات'!$B$2:$B$1001=B209)*('تشخيص الحالات'!$G$2:$G$1001=8)*ROW('تشخيص الحالات'!$B$2:$B$1001))-1),""),"")
I210: =IFERROR(INDEX('تشخيص الحالات'!$D$2:$D$1001,SUMPRODUCT(('تشخيص الحالات'!$B$2:$B$1001=B210)*('تشخيص الحالات'!$G$2:$G$1001=1)*ROW('تشخيص الحالات'!$B$2:$B$1001))-1),"")&IF(SUMPRODUCT(('تشخيص الحالات'!$B$2:$B$1001=B210)*('تشخيص الحالات'!$G$2:$G$1001=2))>0,"، "&IFERROR(INDEX('تشخيص الحالات'!$D$2:$D$1001,SUMPRODUCT(('تشخيص الحالات'!$B$2:$B$1001=B210)*('تشخيص الحالات'!$G$2:$G$1001=2)*ROW('تشخيص الحالات'!$B$2:$B$1001))-1),""),"")&IF(SUMPRODUCT(('تشخيص الحالات'!$B$2:$B$1001=B210)*('تشخيص الحالات'!$G$2:$G$1001=3))>0,"، "&IFERROR(INDEX('تشخيص الحالات'!$D$2:$D$1001,SUMPRODUCT(('تشخيص الحالات'!$B$2:$B$1001=B210)*('تشخيص الحالات'!$G$2:$G$1001=3)*ROW('تشخيص الحالات'!$B$2:$B$1001))-1),""),"")&IF(SUMPRODUCT(('تشخيص الحالات'!$B$2:$B$1001=B210)*('تشخيص الحالات'!$G$2:$G$1001=4))>0,"، "&IFERROR(INDEX('تشخيص الحالات'!$D$2:$D$1001,SUMPRODUCT(('تشخيص الحالات'!$B$2:$B$1001=B210)*('تشخيص الحالات'!$G$2:$G$1001=4)*ROW('تشخيص الحالات'!$B$2:$B$1001))-1),""),"")&IF(SUMPRODUCT(('تشخيص الحالات'!$B$2:$B$1001=B210)*('تشخيص الحالات'!$G$2:$G$1001=5))>0,"، "&IFERROR(INDEX('تشخيص الحالات'!$D$2:$D$1001,SUMPRODUCT(('تشخيص الحالات'!$B$2:$B$1001=B210)*('تشخيص الحالات'!$G$2:$G$1001=5)*ROW('تشخيص الحالات'!$B$2:$B$1001))-1),""),"")&IF(SUMPRODUCT(('تشخيص الحالات'!$B$2:$B$1001=B210)*('تشخيص الحالات'!$G$2:$G$1001=6))>0,"، "&IFERROR(INDEX('تشخيص الحالات'!$D$2:$D$1001,SUMPRODUCT(('تشخيص الحالات'!$B$2:$B$1001=B210)*('تشخيص الحالات'!$G$2:$G$1001=6)*ROW('تشخيص الحالات'!$B$2:$B$1001))-1),""),"")&IF(SUMPRODUCT(('تشخيص الحالات'!$B$2:$B$1001=B210)*('تشخيص الحالات'!$G$2:$G$1001=7))>0,"، "&IFERROR(INDEX('تشخيص الحالات'!$D$2:$D$1001,SUMPRODUCT(('تشخيص الحالات'!$B$2:$B$1001=B210)*('تشخيص الحالات'!$G$2:$G$1001=7)*ROW('تشخيص الحالات'!$B$2:$B$1001))-1),""),"")&IF(SUMPRODUCT(('تشخيص الحالات'!$B$2:$B$1001=B210)*('تشخيص الحالات'!$G$2:$G$1001=8))>0,"، "&IFERROR(INDEX('تشخيص الحالات'!$D$2:$D$1001,SUMPRODUCT(('تشخيص الحالات'!$B$2:$B$1001=B210)*('تشخيص الحالات'!$G$2:$G$1001=8)*ROW('تشخيص الحالات'!$B$2:$B$1001))-1),""),"")
I211: =IFERROR(INDEX('تشخيص الحالات'!$D$2:$D$1001,SUMPRODUCT(('تشخيص الحالات'!$B$2:$B$1001=B211)*('تشخيص الحالات'!$G$2:$G$1001=1)*ROW('تشخيص الحالات'!$B$2:$B$1001))-1),"")&IF(SUMPRODUCT(('تشخيص الحالات'!$B$2:$B$1001=B211)*('تشخيص الحالات'!$G$2:$G$1001=2))>0,"، "&IFERROR(INDEX('تشخيص الحالات'!$D$2:$D$1001,SUMPRODUCT(('تشخيص الحالات'!$B$2:$B$1001=B211)*('تشخيص الحالات'!$G$2:$G$1001=2)*ROW('تشخيص الحالات'!$B$2:$B$1001))-1),""),"")&IF(SUMPRODUCT(('تشخيص الحالات'!$B$2:$B$1001=B211)*('تشخيص الحالات'!$G$2:$G$1001=3))>0,"، "&IFERROR(INDEX('تشخيص الحالات'!$D$2:$D$1001,SUMPRODUCT(('تشخيص الحالات'!$B$2:$B$1001=B211)*('تشخيص الحالات'!$G$2:$G$1001=3)*ROW('تشخيص الحالات'!$B$2:$B$1001))-1),""),"")&IF(SUMPRODUCT(('تشخيص الحالات'!$B$2:$B$1001=B211)*('تشخيص الحالات'!$G$2:$G$1001=4))>0,"، "&IFERROR(INDEX('تشخيص الحالات'!$D$2:$D$1001,SUMPRODUCT(('تشخيص الحالات'!$B$2:$B$1001=B211)*('تشخيص الحالات'!$G$2:$G$1001=4)*ROW('تشخيص الحالات'!$B$2:$B$1001))-1),""),"")&IF(SUMPRODUCT(('تشخيص الحالات'!$B$2:$B$1001=B211)*('تشخيص الحالات'!$G$2:$G$1001=5))>0,"، "&IFERROR(INDEX('تشخيص الحالات'!$D$2:$D$1001,SUMPRODUCT(('تشخيص الحالات'!$B$2:$B$1001=B211)*('تشخيص الحالات'!$G$2:$G$1001=5)*ROW('تشخيص الحالات'!$B$2:$B$1001))-1),""),"")&IF(SUMPRODUCT(('تشخيص الحالات'!$B$2:$B$1001=B211)*('تشخيص الحالات'!$G$2:$G$1001=6))>0,"، "&IFERROR(INDEX('تشخيص الحالات'!$D$2:$D$1001,SUMPRODUCT(('تشخيص الحالات'!$B$2:$B$1001=B211)*('تشخيص الحالات'!$G$2:$G$1001=6)*ROW('تشخيص الحالات'!$B$2:$B$1001))-1),""),"")&IF(SUMPRODUCT(('تشخيص الحالات'!$B$2:$B$1001=B211)*('تشخيص الحالات'!$G$2:$G$1001=7))>0,"، "&IFERROR(INDEX('تشخيص الحالات'!$D$2:$D$1001,SUMPRODUCT(('تشخيص الحالات'!$B$2:$B$1001=B211)*('تشخيص الحالات'!$G$2:$G$1001=7)*ROW('تشخيص الحالات'!$B$2:$B$1001))-1),""),"")&IF(SUMPRODUCT(('تشخيص الحالات'!$B$2:$B$1001=B211)*('تشخيص الحالات'!$G$2:$G$1001=8))>0,"، "&IFERROR(INDEX('تشخيص الحالات'!$D$2:$D$1001,SUMPRODUCT(('تشخيص الحالات'!$B$2:$B$1001=B211)*('تشخيص الحالات'!$G$2:$G$1001=8)*ROW('تشخيص الحالات'!$B$2:$B$1001))-1),""),"")
I212: =IFERROR(INDEX('تشخيص الحالات'!$D$2:$D$1001,SUMPRODUCT(('تشخيص الحالات'!$B$2:$B$1001=B212)*('تشخيص الحالات'!$G$2:$G$1001=1)*ROW('تشخيص الحالات'!$B$2:$B$1001))-1),"")&IF(SUMPRODUCT(('تشخيص الحالات'!$B$2:$B$1001=B212)*('تشخيص الحالات'!$G$2:$G$1001=2))>0,"، "&IFERROR(INDEX('تشخيص الحالات'!$D$2:$D$1001,SUMPRODUCT(('تشخيص الحالات'!$B$2:$B$1001=B212)*('تشخيص الحالات'!$G$2:$G$1001=2)*ROW('تشخيص الحالات'!$B$2:$B$1001))-1),""),"")&IF(SUMPRODUCT(('تشخيص الحالات'!$B$2:$B$1001=B212)*('تشخيص الحالات'!$G$2:$G$1001=3))>0,"، "&IFERROR(INDEX('تشخيص الحالات'!$D$2:$D$1001,SUMPRODUCT(('تشخيص الحالات'!$B$2:$B$1001=B212)*('تشخيص الحالات'!$G$2:$G$1001=3)*ROW('تشخيص الحالات'!$B$2:$B$1001))-1),""),"")&IF(SUMPRODUCT(('تشخيص الحالات'!$B$2:$B$1001=B212)*('تشخيص الحالات'!$G$2:$G$1001=4))>0,"، "&IFERROR(INDEX('تشخيص الحالات'!$D$2:$D$1001,SUMPRODUCT(('تشخيص الحالات'!$B$2:$B$1001=B212)*('تشخيص الحالات'!$G$2:$G$1001=4)*ROW('تشخيص الحالات'!$B$2:$B$1001))-1),""),"")&IF(SUMPRODUCT(('تشخيص الحالات'!$B$2:$B$1001=B212)*('تشخيص الحالات'!$G$2:$G$1001=5))>0,"، "&IFERROR(INDEX('تشخيص الحالات'!$D$2:$D$1001,SUMPRODUCT(('تشخيص الحالات'!$B$2:$B$1001=B212)*('تشخيص الحالات'!$G$2:$G$1001=5)*ROW('تشخيص الحالات'!$B$2:$B$1001))-1),""),"")&IF(SUMPRODUCT(('تشخيص الحالات'!$B$2:$B$1001=B212)*('تشخيص الحالات'!$G$2:$G$1001=6))>0,"، "&IFERROR(INDEX('تشخيص الحالات'!$D$2:$D$1001,SUMPRODUCT(('تشخيص الحالات'!$B$2:$B$1001=B212)*('تشخيص الحالات'!$G$2:$G$1001=6)*ROW('تشخيص الحالات'!$B$2:$B$1001))-1),""),"")&IF(SUMPRODUCT(('تشخيص الحالات'!$B$2:$B$1001=B212)*('تشخيص الحالات'!$G$2:$G$1001=7))>0,"، "&IFERROR(INDEX('تشخيص الحالات'!$D$2:$D$1001,SUMPRODUCT(('تشخيص الحالات'!$B$2:$B$1001=B212)*('تشخيص الحالات'!$G$2:$G$1001=7)*ROW('تشخيص الحالات'!$B$2:$B$1001))-1),""),"")&IF(SUMPRODUCT(('تشخيص الحالات'!$B$2:$B$1001=B212)*('تشخيص الحالات'!$G$2:$G$1001=8))>0,"، "&IFERROR(INDEX('تشخيص الحالات'!$D$2:$D$1001,SUMPRODUCT(('تشخيص الحالات'!$B$2:$B$1001=B212)*('تشخيص الحالات'!$G$2:$G$1001=8)*ROW('تشخيص الحالات'!$B$2:$B$1001))-1),""),"")
